Workbook

Sheet Fig_1A_and_1D
B2: genealogy | D2: Actual ages | G2: digit of 1s column | J2: digit of 10s column | M2: digit of 100s column | R2: https://britroyals.com/royaltree.asp
B3: Parent | C3: Son | D3: Age of father at sons birth | E3: years after sons birth | F3: total age of parent | G3: Age of father at sons birth | H3: years after sons birth | I3: total age of father | J3: Age of father at sons birth | K3: years after sons birth | L3: total age of father | M3: Age of father at sons birth | N3: years after sons birth | O3: total age of father | R3: Name | S3: birth year | T3: death year | U3: parenting age of next person | V3: lifespan | W3: age when descendant born | X3: years remaining
B4: =R4 -> Elizabeth 2 | D4: =W4 -> 22 | E4: =X4 -> 74 | F4: =V4 -> 96 | G4: =MOD(D4, 10) -> 2 | H4: =MOD(E4, 10) -> 4 | I4: =MOD(F4, 10) -> 6 | J4: =MOD(INT(D4/10),10) -> 2 | K4: =MOD(INT(E4/10),10) -> 7 | L4: =MOD(INT(F4/10),10) -> 9 | M4: =MOD(INT(D4/100),10) -> 0 | N4: =MOD(INT(E4/100),10) -> 0 | O4: =MOD(INT(F4/100),10) -> 0 | Q4: 1 | R4: Elizabeth 2 | S4: 1926 | T4: 2022 | U4: 1948 | V4: =T4-S4 -> 96 | W4: =U4-S4 -> 22 | X4: =V4-W4 -> 74
B5: =R5 -> George 6 | D5: =W5 -> 31 | E5: =X5 -> 26 | F5: =V5 -> 57 | G5: =MOD(D5, 10) -> 1 | H5: =MOD(E5, 10) -> 6 | I5: =MOD(F5, 10) -> 7 | J5: =MOD(INT(D5/10),10) -> 3 | K5: =MOD(INT(E5/10),10) -> 2 | L5: =MOD(INT(F5/10),10) -> 5 | M5: =MOD(INT(D5/100),10) -> 0 | N5: =MOD(INT(E5/100),10) -> 0 | O5: =MOD(INT(F5/100),10) -> 0 | Q5: 2 | R5: George 6 | S5: 1895 | T5: 1952 | U5: =S4 -> 1926 | V5: =T5-S5 -> 57 | W5: =U5-S5 -> 31 | X5: =V5-W5 -> 26
B6: =R6 -> George 5 | D6: =W6 -> 30 | E6: =X6 -> 41 | F6: =V6 -> 71 | G6: =MOD(D6, 10) -> 0 | H6: =MOD(E6, 10) -> 1 | I6: =MOD(F6, 10) -> 1 | J6: =MOD(INT(D6/10),10) -> 3 | K6: =MOD(INT(E6/10),10) -> 4 | L6: =MOD(INT(F6/10),10) -> 7 | M6: =MOD(INT(D6/100),10) -> 0 | N6: =MOD(INT(E6/100),10) -> 0 | O6: =MOD(INT(F6/100),10) -> 0 | Q6: 3 | R6: George 5 | S6: 1865 | T6: 1936 | U6: =S5 -> 1895 | V6: =T6-S6 -> 71 | W6: =U6-S6 -> 30 | X6: =V6-W6 -> 41
B7: =R7 -> Edward 7 | D7: =W7 -> 24 | E7: =X7 -> 45 | F7: =V7 -> 69 | G7: =MOD(D7, 10) -> 4 | H7: =MOD(E7, 10) -> 5 | I7: =MOD(F7, 10) -> 9 | J7: =MOD(INT(D7/10),10) -> 2 | K7: =MOD(INT(E7/10),10) -> 4 | L7: =MOD(INT(F7/10),10) -> 6 | M7: =MOD(INT(D7/100),10) -> 0 | N7: =MOD(INT(E7/100),10) -> 0 | O7: =MOD(INT(F7/100),10) -> 0 | Q7: 4 | R7: Edward 7 | S7: 1841 | T7: 1910 | U7: =S6 -> 1865 | V7: =T7-S7 -> 69 | W7: =U7-S7 -> 24 | X7: =V7-W7 -> 45
B8: =R8 -> Victoria | D8: =W8 -> 22 | E8: =X8 -> 60 | F8: =V8 -> 82 | G8: =MOD(D8, 10) -> 2 | H8: =MOD(E8, 10) -> 0 | I8: =MOD(F8, 10) -> 2 | J8: =MOD(INT(D8/10),10) -> 2 | K8: =MOD(INT(E8/10),10) -> 6 | L8: =MOD(INT(F8/10),10) -> 8 | M8: =MOD(INT(D8/100),10) -> 0 | N8: =MOD(INT(E8/100),10) -> 0 | O8: =MOD(INT(F8/100),10) -> 0 | Q8: 5 | R8: Victoria | S8: 1819 | T8: 1901 | U8: =S7 -> 1841 | V8: =T8-S8 -> 82 | W8: =U8-S8 -> 22 | X8: =V8-W8 -> 60
B9: =R9 -> Edward DoK | D9: =W9 -> 52 | E9: =X9 -> 1 | F9: =V9 -> 53 | G9: =MOD(D9, 10) -> 2 | H9: =MOD(E9, 10) -> 1 | I9: =MOD(F9, 10) -> 3 | J9: =MOD(INT(D9/10),10) -> 5 | K9: =MOD(INT(E9/10),10) -> 0 | L9: =MOD(INT(F9/10),10) -> 5 | M9: =MOD(INT(D9/100),10) -> 0 | N9: =MOD(INT(E9/100),10) -> 0 | O9: =MOD(INT(F9/100),10) -> 0 | Q9: 6 | R9: Edward DoK | S9: 1767 | T9: 1820 | U9: =S8 -> 1819 | V9: =T9-S9 -> 53 | W9: =U9-S9 -> 52 | X9: =V9-W9 -> 1
B10: =R10 -> George 3 | D10: =W10 -> 29 | E10: =X10 -> 53 | F10: =V10 -> 82 | G10: =MOD(D10, 10) -> 9 | H10: =MOD(E10, 10) -> 3 | I10: =MOD(F10, 10) -> 2 | J10: =MOD(INT(D10/10),10) -> 2 | K10: =MOD(INT(E10/10),10) -> 5 | L10: =MOD(INT(F10/10),10) -> 8 | M10: =MOD(INT(D10/100),10) -> 0 | N10: =MOD(INT(E10/100),10) -> 0 | O10: =MOD(INT(F10/100),10) -> 0 | Q10: 7 | R10: George 3 | S10: 1738 | T10: 1820 | U10: =S9 -> 1767 | V10: =T10-S10 -> 82 | W10: =U10-S10 -> 29 | X10: =V10-W10 -> 53
B11: =R11 -> Frederick Hano. | D11: =W11 -> 31 | E11: =X11 -> 13 | F11: =V11 -> 44 | G11: =MOD(D11, 10) -> 1 | H11: =MOD(E11, 10) -> 3 | I11: =MOD(F11, 10) -> 4 | J11: =MOD(INT(D11/10),10) -> 3 | K11: =MOD(INT(E11/10),10) -> 1 | L11: =MOD(INT(F11/10),10) -> 4 | M11: =MOD(INT(D11/100),10) -> 0 | N11: =MOD(INT(E11/100),10) -> 0 | O11: =MOD(INT(F11/100),10) -> 0 | Q11: 8 | R11: Frederick Hano. | S11: 1707 | T11: 1751 | U11: =S10 -> 1738 | V11: =T11-S11 -> 44 | W11: =U11-S11 -> 31 | X11: =V11-W11 -> 13
B12: =R12 -> George 2 | D12: =W12 -> 24 | E12: =X12 -> 53 | F12: =V12 -> 77 | G12: =MOD(D12, 10) -> 4 | H12: =MOD(E12, 10) -> 3 | I12: =MOD(F12, 10) -> 7 | J12: =MOD(INT(D12/10),10) -> 2 | K12: =MOD(INT(E12/10),10) -> 5 | L12: =MOD(INT(F12/10),10) -> 7 | M12: =MOD(INT(D12/100),10) -> 0 | N12: =MOD(INT(E12/100),10) -> 0 | O12: =MOD(INT(F12/100),10) -> 0 | Q12: 9 | R12: George 2 | S12: 1683 | T12: 1760 | U12: =S11 -> 1707 | V12: =T12-S12 -> 77 | W12: =U12-S12 -> 24 | X12: =V12-W12 -> 53
B13: =R13 -> George 1 | D13: =W13 -> 23 | E13: =X13 -> 44 | F13: =V13 -> 67 | G13: =MOD(D13, 10) -> 3 | H13: =MOD(E13, 10) -> 4 | I13: =MOD(F13, 10) -> 7 | J13: =MOD(INT(D13/10),10) -> 2 | K13: =MOD(INT(E13/10),10) -> 4 | L13: =MOD(INT(F13/10),10) -> 6 | M13: =MOD(INT(D13/100),10) -> 0 | N13: =MOD(INT(E13/100),10) -> 0 | O13: =MOD(INT(F13/100),10) -> 0 | Q13: 10 | R13: George 1 | S13: 1660 | T13: 1727 | U13: =S12 -> 1683 | V13: =T13-S13 -> 67 | W13: =U13-S13 -> 23 | X13: =V13-W13 -> 44
B14: =R14 -> Sophia Hano. | D14: =W14 -> 30 | E14: =X14 -> 54 | F14: =V14 -> 84 | G14: =MOD(D14, 10) -> 0 | H14: =MOD(E14, 10) -> 4 | I14: =MOD(F14, 10) -> 4 | J14: =MOD(INT(D14/10),10) -> 3 | K14: =MOD(INT(E14/10),10) -> 5 | L14: =MOD(INT(F14/10),10) -> 8 | M14: =MOD(INT(D14/100),10) -> 0 | N14: =MOD(INT(E14/100),10) -> 0 | O14: =MOD(INT(F14/100),10) -> 0 | Q14: 11 | R14: Sophia Hano. | S14: 1630 | T14: 1714 | U14: =S13 -> 1660 | V14: =T14-S14 -> 84 | W14: =U14-S14 -> 30 | X14: =V14-W14 -> 54
B15: =R15 -> Elizabeth Stuart | D15: =W15 -> 34 | E15: =X15 -> 32 | F15: =V15 -> 66 | G15: =MOD(D15, 10) -> 4 | H15: =MOD(E15, 10) -> 2 | I15: =MOD(F15, 10) -> 6 | J15: =MOD(INT(D15/10),10) -> 3 | K15: =MOD(INT(E15/10),10) -> 3 | L15: =MOD(INT(F15/10),10) -> 6 | M15: =MOD(INT(D15/100),10) -> 0 | N15: =MOD(INT(E15/100),10) -> 0 | O15: =MOD(INT(F15/100),10) -> 0 | Q15: 12 | R15: Elizabeth Stuart | S15: 1596 | T15: 1662 | U15: =S14 -> 1630 | V15: =T15-S15 -> 66 | W15: =U15-S15 -> 34 | X15: =V15-W15 -> 32
B16: =R16 -> James 6 Sco. | D16: =W16 -> 30 | E16: =X16 -> 29 | F16: =V16 -> 59 | G16: =MOD(D16, 10) -> 0 | H16: =MOD(E16, 10) -> 9 | I16: =MOD(F16, 10) -> 9 | J16: =MOD(INT(D16/10),10) -> 3 | K16: =MOD(INT(E16/10),10) -> 2 | L16: =MOD(INT(F16/10),10) -> 5 | M16: =MOD(INT(D16/100),10) -> 0 | N16: =MOD(INT(E16/100),10) -> 0 | O16: =MOD(INT(F16/100),10) -> 0 | Q16: 13 | R16: James 6 Sco. | S16: 1566 | T16: 1625 | U16: =S15 -> 1596 | V16: =T16-S16 -> 59 | W16: =U16-S16 -> 30 | X16: =V16-W16 -> 29
... B20: =R20 -> Henry 7 | D20: =W20 -> 32 | E20: =X20 -> 20 | F20: =V20 -> 52 | G20: =MOD(D20, 10) -> 2 | H20: =MOD(E20, 10) -> 0 | I20: =MOD(F20, 10) -> 2 | J20: =MOD(INT(D20/10),10) -> 3 | K20: =MOD(INT(E20/10),10) -> 2 | L20: =MOD(INT(F20/10),10) -> 5 | M20: =MOD(INT(D20/100),10) -> 0 | N20: =MOD(INT(E20/100),10) -> 0 | O20: =MOD(INT(F20/100),10) -> 0 | Q20: 17 | R20: Henry 7 | S20: 1457 | T20: 1509 | U20: =S19 -> 1489 | V20: =T20-S20 -> 52 | W20: =U20-S20 -> 32 | X20: =V20-W20 -> 20
B21: =R21 -> Edmond Tudor | D21: =W21 -> 26 | E21: =X21 -> -1 | F21: =V21 -> 25 | G21: =MOD(D21, 10) -> 6 | I21: =MOD(F21, 10) -> 5 | J21: =MOD(INT(D21/10),10) -> 2 | L21: =MOD(INT(F21/10),10) -> 2 | M21: =MOD(INT(D21/100),10) -> 0 | O21: =MOD(INT(F21/100),10) -> 0 | Q21: 18 | R21: Edmond Tudor | S21: 1431 | T21: 1456 | U21: =S20 -> 1457 | V21: =T21-S21 -> 25 | W21: =U21-S21 -> 26 | X21: =V21-W21 -> -1 | Y21: *father died before he was born
B22: =R22 -> Owen Tudor | D22: =W22 -> 46 | E22: =X22 -> 30 | F22: =V22 -> 76 | G22: =MOD(D22, 10) -> 6 | H22: =MOD(E22, 10) -> 0 | I22: =MOD(F22, 10) -> 6 | J22: =MOD(INT(D22/10),10) -> 4 | K22: =MOD(INT(E22/10),10) -> 3 | L22: =MOD(INT(F22/10),10) -> 7 | M22: =MOD(INT(D22/100),10) -> 0 | N22: =MOD(INT(E22/100),10) -> 0 | O22: =MOD(INT(F22/100),10) -> 0 | Q22: 19 | R22: Owen Tudor | S22: 1385 | T22: 1461 | U22: =S21 -> 1431 | V22: =T22-S22 -> 76 | W22: =U22-S22 -> 46 | X22: =V22-W22 -> 30
C23: total | D23: =SUM(D14:D22) -> 275 | E23: =SUM(E14:E22) -> 214 | F23: =SUM(F14:F22) -> 489
W25: Y_prior_data
S26: All 3 lists combined | AD26: 9 | AF26: factorial | AG26: 1/7 | AH26: 6/7^ | AI26: product
F27: 0 | G27: =COUNTIF(G$4:G$22,$F27) -> 4 | H27: =COUNTIF(H$4:H$22,$F27) -> 4 | I27: =COUNTIF(I$4:I$22,$F27) -> 1 | J27: =COUNTIF(J$4:J$22,$F27) -> 0 | K27: =COUNTIF(K$4:K$22,$F27) -> 2 | L27: =COUNTIF(L$4:L$22,$F27) -> 0 | M27: =COUNTIF(M$4:M$22,$F27) -> 19 | N27: =COUNTIF(N$4:N$22,$F27) -> 18 | O27: =COUNTIF(O$4:O$22,$F27) -> 19 | S27: =G27+Fig_1B_decomp!G27+Fig_1C_decomp!G27 -> 8 | T27: =H27+Fig_1B_decomp!H27+Fig_1C_decomp!H27 -> 11 | U27: =I27+Fig_1B_decomp!I27+Fig_1C_decomp!I27 -> 5 | V27: =J27+Fig_1B_decomp!J27+Fig_1C_decomp!J27 -> 0 | W27: =K27+Fig_1B_decomp!K27+Fig_1C_decomp!K27 -> 8 | X27: =L27+Fig_1B_decomp!L27+Fig_1C_decomp!L27 -> 0 | Y27: =M27+Fig_1B_decomp!M27+Fig_1C_decomp!M27 -> 57 | Z27: =N27+Fig_1B_decomp!N27+Fig_1C_decomp!N27 -> 56 | AA27: =O27+Fig_1B_decomp!O27+Fig_1C_decomp!O27 -> 57 | AE27: 6 | AF27: =(FACT($AD$26)/(FACT(AE27)*FACT($AD$26-AE27))) -> 84 | AG27: =(1/7)^AE27 -> 8.4998598e-06 | AH27: =(6/7)^($AD$26-AE27) -> 0.62973761 | AI27: =AF27*AG27*AH27 -> 0.00044962523
F28: 1 | G28: =COUNTIF(G$4:G$22,$F28) -> 2 | H28: =COUNTIF(H$4:H$22,$F28) -> 3 | I28: =COUNTIF(I$4:I$22,$F28) -> 1 | J28: =COUNTIF(J$4:J$22,$F28) -> 0 | K28: =COUNTIF(K$4:K$22,$F28) -> 1 | L28: =COUNTIF(L$4:L$22,$F28) -> 0 | M28: =COUNTIF(M$4:M$22,$F28) -> 0 | N28: =COUNTIF(N$4:N$22,$F28) -> 0 | O28: =COUNTIF(O$4:O$22,$F28) -> 0 | S28: =G28+Fig_1B_decomp!G28+Fig_1C_decomp!G28 -> 5 | T28: =H28+Fig_1B_decomp!H28+Fig_1C_decomp!H28 -> 6 | U28: =I28+Fig_1B_decomp!I28+Fig_1C_decomp!I28 -> 4 | V28: =J28+Fig_1B_decomp!J28+Fig_1C_decomp!J28 -> 1 | W28: =K28+Fig_1B_decomp!K28+Fig_1C_decomp!K28 -> 9 | X28: =L28+Fig_1B_decomp!L28+Fig_1C_decomp!L28 -> 0 | Y28: =M28+Fig_1B_decomp!M28+Fig_1C_decomp!M28 -> 0 | Z28: =N28+Fig_1B_decomp!N28+Fig_1C_decomp!N28 -> 0 | AA28: =O28+Fig_1B_decomp!O28+Fig_1C_decomp!O28 -> 0 | AE28: 7 | AF28: =(FACT($AD$26)/(FACT(AE28)*FACT($AD$26-AE28))) -> 36 | AG28: =(1/7)^AE28 -> 1.2142657e-06 | AH28: =(6/7)^($AD$26-AE28) -> 0.73469388 | AI28: =AF28*AG28*AH28 -> 3.2116088e-05
F29: 2 | G29: =COUNTIF(G$4:G$22,$F29) -> 4 | H29: =COUNTIF(H$4:H$22,$F29) -> 1 | I29: =COUNTIF(I$4:I$22,$F29) -> 4 | J29: =COUNTIF(J$4:J$22,$F29) -> 9 | K29: =COUNTIF(K$4:K$22,$F29) -> 5 | L29: =COUNTIF(L$4:L$22,$F29) -> 1 | M29: =COUNTIF(M$4:M$22,$F29) -> 0 | N29: =COUNTIF(N$4:N$22,$F29) -> 0 | O29: =COUNTIF(O$4:O$22,$F29) -> 0 | S29: =G29+Fig_1B_decomp!G29+Fig_1C_decomp!G29 -> 11 | T29: =H29+Fig_1B_decomp!H29+Fig_1C_decomp!H29 -> 3 | U29: =I29+Fig_1B_decomp!I29+Fig_1C_decomp!I29 -> 8 | V29: =J29+Fig_1B_decomp!J29+Fig_1C_decomp!J29 -> 29 | W29: =K29+Fig_1B_decomp!K29+Fig_1C_decomp!K29 -> 18 | X29: =L29+Fig_1B_decomp!L29+Fig_1C_decomp!L29 -> 2 | Y29: =M29+Fig_1B_decomp!M29+Fig_1C_decomp!M29 -> 0 | Z29: =N29+Fig_1B_decomp!N29+Fig_1C_decomp!N29 -> 0 | AA29: =O29+Fig_1B_decomp!O29+Fig_1C_decomp!O29 -> 0 | AE29: 8 | AF29: =(FACT($AD$26)/(FACT(AE29)*FACT($AD$26-AE29))) -> 9 | AG29: =(1/7)^AE29 -> 1.7346653e-07 | AH29: =(6/7)^($AD$26-AE29) -> 0.85714286 | AI29: =AF29*AG29*AH29 -> 1.3381703e-06
F30: 3 | G30: =COUNTIF(G$4:G$22,$F30) -> 2 | H30: =COUNTIF(H$4:H$22,$F30) -> 3 | I30: =COUNTIF(I$4:I$22,$F30) -> 1 | J30: =COUNTIF(J$4:J$22,$F30) -> 8 | K30: =COUNTIF(K$4:K$22,$F30) -> 2 | L30: =COUNTIF(L$4:L$22,$F30) -> 1 | M30: =COUNTIF(M$4:M$22,$F30) -> 0 | N30: =COUNTIF(N$4:N$22,$F30) -> 0 | O30: =COUNTIF(O$4:O$22,$F30) -> 0 | S30: =G30+Fig_1B_decomp!G30+Fig_1C_decomp!G30 -> 5 | T30: =H30+Fig_1B_decomp!H30+Fig_1C_decomp!H30 -> 6 | U30: =I30+Fig_1B_decomp!I30+Fig_1C_decomp!I30 -> 3 | V30: =J30+Fig_1B_decomp!J30+Fig_1C_decomp!J30 -> 18 | W30: =K30+Fig_1B_decomp!K30+Fig_1C_decomp!K30 -> 7 | X30: =L30+Fig_1B_decomp!L30+Fig_1C_decomp!L30 -> 6 | Y30: =M30+Fig_1B_decomp!M30+Fig_1C_decomp!M30 -> 0 | Z30: =N30+Fig_1B_decomp!N30+Fig_1C_decomp!N30 -> 0 | AA30: =O30+Fig_1B_decomp!O30+Fig_1C_decomp!O30 -> 0 | AE30: 9 | AF30: =(FACT($AD$26)/(FACT(AE30)*FACT($AD$26-AE30))) -> 1 | AG30: =(1/7)^AE30 -> 2.4780932e-08 | AH30: =(6/7)^($AD$26-AE30) -> 1 | AI30: =AF30*AG30*AH30 -> 2.4780932e-08
F31: 4 | G31: =COUNTIF(G$4:G$22,$F31) -> 4 | H31: =COUNTIF(H$4:H$22,$F31) -> 3 | I31: =COUNTIF(I$4:I$22,$F31) -> 2 | J31: =COUNTIF(J$4:J$22,$F31) -> 1 | K31: =COUNTIF(K$4:K$22,$F31) -> 3 | L31: =COUNTIF(L$4:L$22,$F31) -> 2 | M31: =COUNTIF(M$4:M$22,$F31) -> 0 | N31: =COUNTIF(N$4:N$22,$F31) -> 0 | O31: =COUNTIF(O$4:O$22,$F31) -> 0 | S31: =G31+Fig_1B_decomp!G31+Fig_1C_decomp!G31 -> 6 | T31: =H31+Fig_1B_decomp!H31+Fig_1C_decomp!H31 -> 5 | U31: =I31+Fig_1B_decomp!I31+Fig_1C_decomp!I31 -> 6 | V31: =J31+Fig_1B_decomp!J31+Fig_1C_decomp!J31 -> 6 | W31: =K31+Fig_1B_decomp!K31+Fig_1C_decomp!K31 -> 7 | X31: =L31+Fig_1B_decomp!L31+Fig_1C_decomp!L31 -> 13 | Y31: =M31+Fig_1B_decomp!M31+Fig_1C_decomp!M31 -> 0 | Z31: =N31+Fig_1B_decomp!N31+Fig_1C_decomp!N31 -> 0 | AA31: =O31+Fig_1B_decomp!O31+Fig_1C_decomp!O31 -> 0 | AH31: final product | AI31: =SUM(AI27:AI30) -> 0.00048310427
F32: 5 | G32: =COUNTIF(G$4:G$22,$F32) -> 0 | H32: =COUNTIF(H$4:H$22,$F32) -> 1 | I32: =COUNTIF(I$4:I$22,$F32) -> 2 | J32: =COUNTIF(J$4:J$22,$F32) -> 1 | K32: =COUNTIF(K$4:K$22,$F32) -> 3 | L32: =COUNTIF(L$4:L$22,$F32) -> 5 | M32: =COUNTIF(M$4:M$22,$F32) -> 0 | N32: =COUNTIF(N$4:N$22,$F32) -> 0 | O32: =COUNTIF(O$4:O$22,$F32) -> 0 | S32: =G32+Fig_1B_decomp!G32+Fig_1C_decomp!G32 -> 4 | T32: =H32+Fig_1B_decomp!H32+Fig_1C_decomp!H32 -> 4 | U32: =I32+Fig_1B_decomp!I32+Fig_1C_decomp!I32 -> 5 | V32: =J32+Fig_1B_decomp!J32+Fig_1C_decomp!J32 -> 3 | W32: =K32+Fig_1B_decomp!K32+Fig_1C_decomp!K32 -> 5 | X32: =L32+Fig_1B_decomp!L32+Fig_1C_decomp!L32 -> 10 | Y32: =M32+Fig_1B_decomp!M32+Fig_1C_decomp!M32 -> 0 | Z32: =N32+Fig_1B_decomp!N32+Fig_1C_decomp!N32 -> 0 | AA32: =O32+Fig_1B_decomp!O32+Fig_1C_decomp!O32 -> 0 | AH32: 1 in N chance | AI32: =1/AI31 -> 2069.9465
F33: 6 | G33: =COUNTIF(G$4:G$22,$F33) -> 2 | H33: =COUNTIF(H$4:H$22,$F33) -> 1 | I33: =COUNTIF(I$4:I$22,$F33) -> 3 | J33: =COUNTIF(J$4:J$22,$F33) -> 0 | K33: =COUNTIF(K$4:K$22,$F33) -> 1 | L33: =COUNTIF(L$4:L$22,$F33) -> 3 | M33: =COUNTIF(M$4:M$22,$F33) -> 0 | N33: =COUNTIF(N$4:N$22,$F33) -> 0 | O33: =COUNTIF(O$4:O$22,$F33) -> 0 | S33: =G33+Fig_1B_decomp!G33+Fig_1C_decomp!G33 -> 3 | T33: =H33+Fig_1B_decomp!H33+Fig_1C_decomp!H33 -> 6 | U33: =I33+Fig_1B_decomp!I33+Fig_1C_decomp!I33 -> 8 | V33: =J33+Fig_1B_decomp!J33+Fig_1C_decomp!J33 -> 0 | W33: =K33+Fig_1B_decomp!K33+Fig_1C_decomp!K33 -> 1 | X33: =L33+Fig_1B_decomp!L33+Fig_1C_decomp!L33 -> 12 | Y33: =M33+Fig_1B_decomp!M33+Fig_1C_decomp!M33 -> 0 | Z33: =N33+Fig_1B_decomp!N33+Fig_1C_decomp!N33 -> 0 | AA33: =O33+Fig_1B_decomp!O33+Fig_1C_decomp!O33 -> 0
F34: 7 | G34: =COUNTIF(G$4:G$22,$F34) -> 0 | H34: =COUNTIF(H$4:H$22,$F34) -> 0 | I34: =COUNTIF(I$4:I$22,$F34) -> 3 | J34: =COUNTIF(J$4:J$22,$F34) -> 0 | K34: =COUNTIF(K$4:K$22,$F34) -> 1 | L34: =COUNTIF(L$4:L$22,$F34) -> 3 | M34: =COUNTIF(M$4:M$22,$F34) -> 0 | N34: =COUNTIF(N$4:N$22,$F34) -> 0 | O34: =COUNTIF(O$4:O$22,$F34) -> 0 | S34: =G34+Fig_1B_decomp!G34+Fig_1C_decomp!G34 -> 5 | T34: =H34+Fig_1B_decomp!H34+Fig_1C_decomp!H34 -> 6 | U34: =I34+Fig_1B_decomp!I34+Fig_1C_decomp!I34 -> 6 | V34: =J34+Fig_1B_decomp!J34+Fig_1C_decomp!J34 -> 0 | W34: =K34+Fig_1B_decomp!K34+Fig_1C_decomp!K34 -> 1 | X34: =L34+Fig_1B_decomp!L34+Fig_1C_decomp!L34 -> 7 | Y34: =M34+Fig_1B_decomp!M34+Fig_1C_decomp!M34 -> 0 | Z34: =N34+Fig_1B_decomp!N34+Fig_1C_decomp!N34 -> 0 | AA34: =O34+Fig_1B_decomp!O34+Fig_1C_decomp!O34 -> 0
F35: 8 | G35: =COUNTIF(G$4:G$22,$F35) -> 0 | H35: =COUNTIF(H$4:H$22,$F35) -> 0 | I35: =COUNTIF(I$4:I$22,$F35) -> 0 | J35: =COUNTIF(J$4:J$22,$F35) -> 0 | K35: =COUNTIF(K$4:K$22,$F35) -> 0 | L35: =COUNTIF(L$4:L$22,$F35) -> 3 | M35: =COUNTIF(M$4:M$22,$F35) -> 0 | N35: =COUNTIF(N$4:N$22,$F35) -> 0 | O35: =COUNTIF(O$4:O$22,$F35) -> 0 | S35: =G35+Fig_1B_decomp!G35+Fig_1C_decomp!G35 -> 2 | T35: =H35+Fig_1B_decomp!H35+Fig_1C_decomp!H35 -> 3 | U35: =I35+Fig_1B_decomp!I35+Fig_1C_decomp!I35 -> 4 | V35: =J35+Fig_1B_decomp!J35+Fig_1C_decomp!J35 -> 0 | W35: =K35+Fig_1B_decomp!K35+Fig_1C_decomp!K35 -> 0 | X35: =L35+Fig_1B_decomp!L35+Fig_1C_decomp!L35 -> 6 | Y35: =M35+Fig_1B_decomp!M35+Fig_1C_decomp!M35 -> 0 | Z35: =N35+Fig_1B_decomp!N35+Fig_1C_decomp!N35 -> 0 | AA35: =O35+Fig_1B_decomp!O35+Fig_1C_decomp!O35 -> 0
F36: 9 | G36: =COUNTIF(G$4:G$22,$F36) -> 1 | H36: =COUNTIF(H$4:H$22,$F36) -> 2 | I36: =COUNTIF(I$4:I$22,$F36) -> 2 | J36: =COUNTIF(J$4:J$22,$F36) -> 0 | K36: =COUNTIF(K$4:K$22,$F36) -> 0 | L36: =COUNTIF(L$4:L$22,$F36) -> 1 | M36: =COUNTIF(M$4:M$22,$F36) -> 0 | N36: =COUNTIF(N$4:N$22,$F36) -> 0 | O36: =COUNTIF(O$4:O$22,$F36) -> 0 | S36: =G36+Fig_1B_decomp!G36+Fig_1C_decomp!G36 -> 8 | T36: =H36+Fig_1B_decomp!H36+Fig_1C_decomp!H36 -> 6 | U36: =I36+Fig_1B_decomp!I36+Fig_1C_decomp!I36 -> 8 | V36: =J36+Fig_1B_decomp!J36+Fig_1C_decomp!J36 -> 0 | W36: =K36+Fig_1B_decomp!K36+Fig_1C_decomp!K36 -> 0 | X36: =L36+Fig_1B_decomp!L36+Fig_1C_decomp!L36 -> 1 | Y36: =M36+Fig_1B_decomp!M36+Fig_1C_decomp!M36 -> 0 | Z36: =N36+Fig_1B_decomp!N36+Fig_1C_decomp!N36 -> 0 | AA36: =O36+Fig_1B_decomp!O36+Fig_1C_decomp!O36 -> 0
W37: =SUM(W27:W36) -> 56

Sheet Fig_1B_decomp
B2: genealogy | D2: Actual ages | G2: digit of 1s column | J2: digit of 10s column | M2: digit of 100s column | S2: https://en.wikipedia.org/wiki/Family_tree_of_French_monarchs
B3: Father | C3: Son | D3: Age of father at sons birth | E3: years after sons birth | F3: total age of father | G3: Age of father at sons birth | H3: years after sons birth | I3: total age of father | J3: Age of father at sons birth | K3: years after sons birth | L3: total age of father | M3: Age of father at sons birth | N3: years after sons birth | O3: total age of father | R3: Name | S3: birth year | T3: death year | U3: parenting age of next person | V3: lifespan | W3: age when descendant born | X3: years remaining
B4: =R4 -> Louis Philippe 1 | D4: =W4 -> 37 | E4: =X4 -> 40 | F4: =V4 -> 77 | G4: =MOD(D4, 10) -> 7 | H4: =MOD(E4, 10) -> 0 | I4: =MOD(F4, 10) -> 7 | J4: =MOD(INT(D4/10),10) -> 3 | K4: =MOD(INT(E4/10),10) -> 4 | L4: =MOD(INT(F4/10),10) -> 7 | M4: =MOD(INT(D4/100),10) -> 0 | N4: =MOD(INT(E4/100),10) -> 0 | O4: =MOD(INT(F4/100),10) -> 0 | Q4: 1 | R4: Louis Philippe 1 | S4: 1773 | T4: 1850 | U4: 1810 | V4: =T4-S4 -> 77 | W4: =U4-S4 -> 37 | X4: =V4-W4 -> 40
B5: =R5 -> Louis Philippe 2 | D5: =W5 -> 26 | E5: =X5 -> 20 | F5: =V5 -> 46 | G5: =MOD(D5, 10) -> 6 | H5: =MOD(E5, 10) -> 0 | I5: =MOD(F5, 10) -> 6 | J5: =MOD(INT(D5/10),10) -> 2 | K5: =MOD(INT(E5/10),10) -> 2 | L5: =MOD(INT(F5/10),10) -> 4 | M5: =MOD(INT(D5/100),10) -> 0 | N5: =MOD(INT(E5/100),10) -> 0 | O5: =MOD(INT(F5/100),10) -> 0 | Q5: 2 | R5: Louis Philippe 2 | S5: 1747 | T5: 1793 | U5: =S4 -> 1773 | V5: =T5-S5 -> 46 | W5: =U5-S5 -> 26 | X5: =V5-W5 -> 20
B6: =R6 -> Louis Philippe 1 | D6: =W6 -> 22 | E6: =X6 -> 38 | F6: =V6 -> 60 | G6: =MOD(D6, 10) -> 2 | H6: =MOD(E6, 10) -> 8 | I6: =MOD(F6, 10) -> 0 | J6: =MOD(INT(D6/10),10) -> 2 | K6: =MOD(INT(E6/10),10) -> 3 | L6: =MOD(INT(F6/10),10) -> 6 | M6: =MOD(INT(D6/100),10) -> 0 | N6: =MOD(INT(E6/100),10) -> 0 | O6: =MOD(INT(F6/100),10) -> 0 | Q6: 3 | R6: Louis Philippe 1 | S6: 1725 | T6: 1785 | U6: =S5 -> 1747 | V6: =T6-S6 -> 60 | W6: =U6-S6 -> 22 | X6: =V6-W6 -> 38
B7: =R7 -> Louis | D7: =W7 -> 22 | E7: =X7 -> 27 | F7: =V7 -> 49 | G7: =MOD(D7, 10) -> 2 | H7: =MOD(E7, 10) -> 7 | I7: =MOD(F7, 10) -> 9 | J7: =MOD(INT(D7/10),10) -> 2 | K7: =MOD(INT(E7/10),10) -> 2 | L7: =MOD(INT(F7/10),10) -> 4 | M7: =MOD(INT(D7/100),10) -> 0 | N7: =MOD(INT(E7/100),10) -> 0 | O7: =MOD(INT(F7/100),10) -> 0 | Q7: 4 | R7: Louis | S7: 1703 | T7: 1752 | U7: =S6 -> 1725 | V7: =T7-S7 -> 49 | W7: =U7-S7 -> 22 | X7: =V7-W7 -> 27
B8: =R8 -> Philippe 2 | D8: =W8 -> 29 | E8: =X8 -> 20 | F8: =V8 -> 49 | G8: =MOD(D8, 10) -> 9 | H8: =MOD(E8, 10) -> 0 | I8: =MOD(F8, 10) -> 9 | J8: =MOD(INT(D8/10),10) -> 2 | K8: =MOD(INT(E8/10),10) -> 2 | L8: =MOD(INT(F8/10),10) -> 4 | M8: =MOD(INT(D8/100),10) -> 0 | N8: =MOD(INT(E8/100),10) -> 0 | O8: =MOD(INT(F8/100),10) -> 0 | Q8: 5 | R8: Philippe 2 | S8: 1674 | T8: 1723 | U8: =S7 -> 1703 | V8: =T8-S8 -> 49 | W8: =U8-S8 -> 29 | X8: =V8-W8 -> 20
B9: =R9 -> Philippe 1 | D9: =W9 -> 34 | E9: =X9 -> 27 | F9: =V9 -> 61 | G9: =MOD(D9, 10) -> 4 | H9: =MOD(E9, 10) -> 7 | I9: =MOD(F9, 10) -> 1 | J9: =MOD(INT(D9/10),10) -> 3 | K9: =MOD(INT(E9/10),10) -> 2 | L9: =MOD(INT(F9/10),10) -> 6 | M9: =MOD(INT(D9/100),10) -> 0 | N9: =MOD(INT(E9/100),10) -> 0 | O9: =MOD(INT(F9/100),10) -> 0 | Q9: 6 | R9: Philippe 1 | S9: 1640 | T9: 1701 | U9: =S8 -> 1674 | V9: =T9-S9 -> 61 | W9: =U9-S9 -> 34 | X9: =V9-W9 -> 27
B10: =R10 -> Louis 8 | D10: =W10 -> 30 | E10: =X10 -> 3 | F10: =V10 -> 33 | G10: =MOD(D10, 10) -> 0 | H10: =MOD(E10, 10) -> 3 | I10: =MOD(F10, 10) -> 3 | J10: =MOD(INT(D10/10),10) -> 3 | K10: =MOD(INT(E10/10),10) -> 0 | L10: =MOD(INT(F10/10),10) -> 3 | M10: =MOD(INT(D10/100),10) -> 0 | N10: =MOD(INT(E10/100),10) -> 0 | O10: =MOD(INT(F10/100),10) -> 0 | Q10: 7 | R10: Louis 8 | S10: 1610 | T10: 1643 | U10: =S9 -> 1640 | V10: =T10-S10 -> 33 | W10: =U10-S10 -> 30 | X10: =V10-W10 -> 3
B11: =R11 -> Henry 4 | D11: =W11 -> 57 | E11: =X11 -> 0 | F11: =V11 -> 57 | G11: =MOD(D11, 10) -> 7 | H11: =MOD(E11, 10) -> 0 | I11: =MOD(F11, 10) -> 7 | J11: =MOD(INT(D11/10),10) -> 5 | K11: =MOD(INT(E11/10),10) -> 0 | L11: =MOD(INT(F11/10),10) -> 5 | M11: =MOD(INT(D11/100),10) -> 0 | N11: =MOD(INT(E11/100),10) -> 0 | O11: =MOD(INT(F11/100),10) -> 0 | Q11: 8 | R11: Henry 4 | S11: 1553 | T11: 1610 | U11: =S10 -> 1610 | V11: =T11-S11 -> 57 | W11: =U11-S11 -> 57 | X11: =V11-W11 -> 0
B12: =R12 -> Antoine | D12: =W12 -> 35 | E12: =X12 -> 9 | F12: =V12 -> 44 | G12: =MOD(D12, 10) -> 5 | H12: =MOD(E12, 10) -> 9 | I12: =MOD(F12, 10) -> 4 | J12: =MOD(INT(D12/10),10) -> 3 | K12: =MOD(INT(E12/10),10) -> 0 | L12: =MOD(INT(F12/10),10) -> 4 | M12: =MOD(INT(D12/100),10) -> 0 | N12: =MOD(INT(E12/100),10) -> 0 | O12: =MOD(INT(F12/100),10) -> 0 | Q12: 9 | R12: Antoine | S12: 1518 | T12: 1562 | U12: =S11 -> 1553 | V12: =T12-S12 -> 44 | W12: =U12-S12 -> 35 | X12: =V12-W12 -> 9
B13: =R13 -> Charles | D13: =W13 -> 29 | E13: =X13 -> 19 | F13: =V13 -> 48 | G13: =MOD(D13, 10) -> 9 | H13: =MOD(E13, 10) -> 9 | I13: =MOD(F13, 10) -> 8 | J13: =MOD(INT(D13/10),10) -> 2 | K13: =MOD(INT(E13/10),10) -> 1 | L13: =MOD(INT(F13/10),10) -> 4 | M13: =MOD(INT(D13/100),10) -> 0 | N13: =MOD(INT(E13/100),10) -> 0 | O13: =MOD(INT(F13/100),10) -> 0 | Q13: 10 | R13: Charles | S13: 1489 | T13: 1537 | U13: =S12 -> 1518 | V13: =T13-S13 -> 48 | W13: =U13-S13 -> 29 | X13: =V13-W13 -> 19
B14: =R14 -> Francis | D14: =W14 -> 19 | E14: =X14 -> 6 | F14: =V14 -> 25 | G14: =MOD(D14, 10) -> 9 | H14: =MOD(E14, 10) -> 6 | I14: =MOD(F14, 10) -> 5 | J14: =MOD(INT(D14/10),10) -> 1 | K14: =MOD(INT(E14/10),10) -> 0 | L14: =MOD(INT(F14/10),10) -> 2 | M14: =MOD(INT(D14/100),10) -> 0 | N14: =MOD(INT(E14/100),10) -> 0 | O14: =MOD(INT(F14/100),10) -> 0 | Q14: 11 | R14: Francis | S14: 1470 | T14: 1495 | U14: =S13 -> 1489 | V14: =T14-S14 -> 25 | W14: =U14-S14 -> 19 | X14: =V14-W14 -> 6
B15: =R15 -> John 8 | D15: =W15 -> 45 | E15: =X15 -> 7 | F15: =V15 -> 52 | G15: =MOD(D15, 10) -> 5 | H15: =MOD(E15, 10) -> 7 | I15: =MOD(F15, 10) -> 2 | J15: =MOD(INT(D15/10),10) -> 4 | K15: =MOD(INT(E15/10),10) -> 0 | L15: =MOD(INT(F15/10),10) -> 5 | M15: =MOD(INT(D15/100),10) -> 0 | N15: =MOD(INT(E15/100),10) -> 0 | O15: =MOD(INT(F15/100),10) -> 0 | Q15: 12 | R15: John 8 | S15: 1425 | T15: 1477 | U15: =S14 -> 1470 | V15: =T15-S15 -> 52 | W15: =U15-S15 -> 45 | X15: =V15-W15 -> 7
B16: =R16 -> Louis | D16: =W16 -> 49 | E16: =X16 -> 21 | F16: =V16 -> 70 | G16: =MOD(D16, 10) -> 9 | H16: =MOD(E16, 10) -> 1 | I16: =MOD(F16, 10) -> 0 | J16: =MOD(INT(D16/10),10) -> 4 | K16: =MOD(INT(E16/10),10) -> 2 | L16: =MOD(INT(F16/10),10) -> 7 | M16: =MOD(INT(D16/100),10) -> 0 | N16: =MOD(INT(E16/100),10) -> 0 | O16: =MOD(INT(F16/100),10) -> 0 | Q16: 13 | R16: Louis | S16: 1376 | T16: 1446 | U16: =S15 -> 1425 | V16: =T16-S16 -> 70 | W16: =U16-S16 -> 49 | X16: =V16-W16 -> 21
... B22: =R22 -> Louis 8 | D22: =W22 -> 27 | E22: =X22 -> 12 | F22: =V22 -> 39 | G22: =MOD(D22, 10) -> 7 | H22: =MOD(E22, 10) -> 2 | I22: =MOD(F22, 10) -> 9 | J22: =MOD(INT(D22/10),10) -> 2 | K22: =MOD(INT(E22/10),10) -> 1 | L22: =MOD(INT(F22/10),10) -> 3 | M22: =MOD(INT(D22/100),10) -> 0 | N22: =MOD(INT(E22/100),10) -> 0 | O22: =MOD(INT(F22/100),10) -> 0 | Q22: 19 | R22: Louis 8 | S22: 1187 | T22: 1226 | U22: =S21 -> 1214 | V22: =T22-S22 -> 39 | W22: =U22-S22 -> 27 | X22: =V22-W22 -> 12
C23: total | D23: =SUM(D14:D22) -> 302 | E23: =SUM(E14:E22) -> 155 | F23: =SUM(F14:F22) -> 457
F27: 0 | G27: =COUNTIF(G$4:G$22,$F27) -> 2 | H27: =COUNTIF(H$4:H$22,$F27) -> 4 | I27: =COUNTIF(I$4:I$22,$F27) -> 2 | J27: =COUNTIF(J$4:J$22,$F27) -> 0 | K27: =COUNTIF(K$4:K$22,$F27) -> 5 | L27: =COUNTIF(L$4:L$22,$F27) -> 0 | M27: =COUNTIF(M$4:M$22,$F27) -> 19 | N27: =COUNTIF(N$4:N$22,$F27) -> 19 | O27: =COUNTIF(O$4:O$22,$F27) -> 19
F28: 1 | G28: =COUNTIF(G$4:G$22,$F28) -> 0 | H28: =COUNTIF(H$4:H$22,$F28) -> 1 | I28: =COUNTIF(I$4:I$22,$F28) -> 2 | J28: =COUNTIF(J$4:J$22,$F28) -> 1 | K28: =COUNTIF(K$4:K$22,$F28) -> 5 | L28: =COUNTIF(L$4:L$22,$F28) -> 0 | M28: =COUNTIF(M$4:M$22,$F28) -> 0 | N28: =COUNTIF(N$4:N$22,$F28) -> 0 | O28: =COUNTIF(O$4:O$22,$F28) -> 0
F29: 2 | G29: =COUNTIF(G$4:G$22,$F29) -> 4 | H29: =COUNTIF(H$4:H$22,$F29) -> 2 | I29: =COUNTIF(I$4:I$22,$F29) -> 2 | J29: =COUNTIF(J$4:J$22,$F29) -> 8 | K29: =COUNTIF(K$4:K$22,$F29) -> 6 | L29: =COUNTIF(L$4:L$22,$F29) -> 1 | M29: =COUNTIF(M$4:M$22,$F29) -> 0 | N29: =COUNTIF(N$4:N$22,$F29) -> 0 | O29: =COUNTIF(O$4:O$22,$F29) -> 0
F30: 3 | G30: =COUNTIF(G$4:G$22,$F30) -> 1 | H30: =COUNTIF(H$4:H$22,$F30) -> 1 | I30: =COUNTIF(I$4:I$22,$F30) -> 2 | J30: =COUNTIF(J$4:J$22,$F30) -> 5 | K30: =COUNTIF(K$4:K$22,$F30) -> 2 | L30: =COUNTIF(L$4:L$22,$F30) -> 2 | M30: =COUNTIF(M$4:M$22,$F30) -> 0 | N30: =COUNTIF(N$4:N$22,$F30) -> 0 | O30: =COUNTIF(O$4:O$22,$F30) -> 0
F31: 4 | G31: =COUNTIF(G$4:G$22,$F31) -> 1 | H31: =COUNTIF(H$4:H$22,$F31) -> 1 | I31: =COUNTIF(I$4:I$22,$F31) -> 1 | J31: =COUNTIF(J$4:J$22,$F31) -> 4 | K31: =COUNTIF(K$4:K$22,$F31) -> 1 | L31: =COUNTIF(L$4:L$22,$F31) -> 7 | M31: =COUNTIF(M$4:M$22,$F31) -> 0 | N31: =COUNTIF(N$4:N$22,$F31) -> 0 | O31: =COUNTIF(O$4:O$22,$F31) -> 0
F32: 5 | G32: =COUNTIF(G$4:G$22,$F32) -> 3 | H32: =COUNTIF(H$4:H$22,$F32) -> 0 | I32: =COUNTIF(I$4:I$22,$F32) -> 1 | J32: =COUNTIF(J$4:J$22,$F32) -> 1 | K32: =COUNTIF(K$4:K$22,$F32) -> 0 | L32: =COUNTIF(L$4:L$22,$F32) -> 3 | M32: =COUNTIF(M$4:M$22,$F32) -> 0 | N32: =COUNTIF(N$4:N$22,$F32) -> 0 | O32: =COUNTIF(O$4:O$22,$F32) -> 0
F33: 6 | G33: =COUNTIF(G$4:G$22,$F33) -> 1 | H33: =COUNTIF(H$4:H$22,$F33) -> 1 | I33: =COUNTIF(I$4:I$22,$F33) -> 2 | J33: =COUNTIF(J$4:J$22,$F33) -> 0 | K33: =COUNTIF(K$4:K$22,$F33) -> 0 | L33: =COUNTIF(L$4:L$22,$F33) -> 4 | M33: =COUNTIF(M$4:M$22,$F33) -> 0 | N33: =COUNTIF(N$4:N$22,$F33) -> 0 | O33: =COUNTIF(O$4:O$22,$F33) -> 0
F34: 7 | G34: =COUNTIF(G$4:G$22,$F34) -> 3 | H34: =COUNTIF(H$4:H$22,$F34) -> 4 | I34: =COUNTIF(I$4:I$22,$F34) -> 2 | J34: =COUNTIF(J$4:J$22,$F34) -> 0 | K34: =COUNTIF(K$4:K$22,$F34) -> 0 | L34: =COUNTIF(L$4:L$22,$F34) -> 2 | M34: =COUNTIF(M$4:M$22,$F34) -> 0 | N34: =COUNTIF(N$4:N$22,$F34) -> 0 | O34: =COUNTIF(O$4:O$22,$F34) -> 0
F35: 8 | G35: =COUNTIF(G$4:G$22,$F35) -> 0 | H35: =COUNTIF(H$4:H$22,$F35) -> 3 | I35: =COUNTIF(I$4:I$22,$F35) -> 1 | J35: =COUNTIF(J$4:J$22,$F35) -> 0 | K35: =COUNTIF(K$4:K$22,$F35) -> 0 | L35: =COUNTIF(L$4:L$22,$F35) -> 0 | M35: =COUNTIF(M$4:M$22,$F35) -> 0 | N35: =COUNTIF(N$4:N$22,$F35) -> 0 | O35: =COUNTIF(O$4:O$22,$F35) -> 0
F36: 9 | G36: =COUNTIF(G$4:G$22,$F36) -> 4 | H36: =COUNTIF(H$4:H$22,$F36) -> 2 | I36: =COUNTIF(I$4:I$22,$F36) -> 4 | J36: =COUNTIF(J$4:J$22,$F36) -> 0 | K36: =COUNTIF(K$4:K$22,$F36) -> 0 | L36: =COUNTIF(L$4:L$22,$F36) -> 0 | M36: =COUNTIF(M$4:M$22,$F36) -> 0 | N36: =COUNTIF(N$4:N$22,$F36) -> 0 | O36: =COUNTIF(O$4:O$22,$F36) -> 0

Sheet Fig_1C_decomp
B2: genealogy | D2: Actual ages | G2: digit of 1s column | J2: digit of 10s column | M2: digit of 100s column | R2: https://en.wikipedia.org/wiki/Family_tree_of_Japanese_monarchs
B3: Father | C3: Son | D3: Age of father at sons birth | E3: years after sons birth | F3: total age of father | G3: Age of father at sons birth | H3: years after sons birth | I3: total age of father | J3: Age of father at sons birth | K3: years after sons birth | L3: total age of father | M3: Age of father at sons birth | N3: years after sons birth | O3: total age of father | R3: Name | S3: birth year | T3: death year | U3: parenting age of next person | V3: lifespan | W3: age when descendant born | X3: years remaining
B4: =R4 -> Hirohito | D4: =W4 -> 32 | E4: =X4 -> 56 | F4: =V4 -> 88 | G4: =MOD(D4, 10) -> 2 | H4: =MOD(E4, 10) -> 6 | I4: =MOD(F4, 10) -> 8 | J4: =MOD(INT(D4/10),10) -> 3 | K4: =MOD(INT(E4/10),10) -> 5 | L4: =MOD(INT(F4/10),10) -> 8 | M4: =MOD(INT(D4/100),10) -> 0 | N4: =MOD(INT(E4/100),10) -> 0 | O4: =MOD(INT(F4/100),10) -> 0 | Q4: 1 | R4: Hirohito | S4: 1901 | T4: 1989 | U4: 1933 | V4: =T4-S4 -> 88 | W4: =U4-S4 -> 32 | X4: =V4-W4 -> 56
B5: =R5 -> Yoshihito | D5: =W5 -> 22 | E5: =X5 -> 25 | F5: =V5 -> 47 | G5: =MOD(D5, 10) -> 2 | H5: =MOD(E5, 10) -> 5 | I5: =MOD(F5, 10) -> 7 | J5: =MOD(INT(D5/10),10) -> 2 | K5: =MOD(INT(E5/10),10) -> 2 | L5: =MOD(INT(F5/10),10) -> 4 | M5: =MOD(INT(D5/100),10) -> 0 | N5: =MOD(INT(E5/100),10) -> 0 | O5: =MOD(INT(F5/100),10) -> 0 | Q5: 2 | R5: Yoshihito | S5: 1879 | T5: 1926 | U5: =S4 -> 1901 | V5: =T5-S5 -> 47 | W5: =U5-S5 -> 22 | X5: =V5-W5 -> 25
B6: =R6 -> Mutsuhito | D6: =W6 -> 27 | E6: =X6 -> 33 | F6: =V6 -> 60 | G6: =MOD(D6, 10) -> 7 | H6: =MOD(E6, 10) -> 3 | I6: =MOD(F6, 10) -> 0 | J6: =MOD(INT(D6/10),10) -> 2 | K6: =MOD(INT(E6/10),10) -> 3 | L6: =MOD(INT(F6/10),10) -> 6 | M6: =MOD(INT(D6/100),10) -> 0 | N6: =MOD(INT(E6/100),10) -> 0 | O6: =MOD(INT(F6/100),10) -> 0 | Q6: 3 | R6: Mutsuhito | S6: 1852 | T6: 1912 | U6: =S5 -> 1879 | V6: =T6-S6 -> 60 | W6: =U6-S6 -> 27 | X6: =V6-W6 -> 33
B7: =R7 -> Osahito | D7: =W7 -> 21 | E7: =X7 -> 15 | F7: =V7 -> 36 | G7: =MOD(D7, 10) -> 1 | H7: =MOD(E7, 10) -> 5 | I7: =MOD(F7, 10) -> 6 | J7: =MOD(INT(D7/10),10) -> 2 | K7: =MOD(INT(E7/10),10) -> 1 | L7: =MOD(INT(F7/10),10) -> 3 | M7: =MOD(INT(D7/100),10) -> 0 | N7: =MOD(INT(E7/100),10) -> 0 | O7: =MOD(INT(F7/100),10) -> 0 | Q7: 4 | R7: Osahito | S7: 1831 | T7: 1867 | U7: =S6 -> 1852 | V7: =T7-S7 -> 36 | W7: =U7-S7 -> 21 | X7: =V7-W7 -> 15
B8: =R8 -> Ayahito | D8: =W8 -> 31 | E8: =X8 -> 15 | F8: =V8 -> 46 | G8: =MOD(D8, 10) -> 1 | H8: =MOD(E8, 10) -> 5 | I8: =MOD(F8, 10) -> 6 | J8: =MOD(INT(D8/10),10) -> 3 | K8: =MOD(INT(E8/10),10) -> 1 | L8: =MOD(INT(F8/10),10) -> 4 | M8: =MOD(INT(D8/100),10) -> 0 | N8: =MOD(INT(E8/100),10) -> 0 | O8: =MOD(INT(F8/100),10) -> 0 | Q8: 5 | R8: Ayahito | S8: 1800 | T8: 1846 | U8: =S7 -> 1831 | V8: =T8-S8 -> 46 | W8: =U8-S8 -> 31 | X8: =V8-W8 -> 15
B9: =R9 -> Morohito | D9: =W9 -> 29 | E9: =X9 -> 40 | F9: =V9 -> 69 | G9: =MOD(D9, 10) -> 9 | H9: =MOD(E9, 10) -> 0 | I9: =MOD(F9, 10) -> 9 | J9: =MOD(INT(D9/10),10) -> 2 | K9: =MOD(INT(E9/10),10) -> 4 | L9: =MOD(INT(F9/10),10) -> 6 | M9: =MOD(INT(D9/100),10) -> 0 | N9: =MOD(INT(E9/100),10) -> 0 | O9: =MOD(INT(F9/100),10) -> 0 | Q9: 6 | R9: Morohito | S9: 1771 | T9: 1840 | U9: =S8 -> 1800 | V9: =T9-S9 -> 69 | W9: =U9-S9 -> 29 | X9: =V9-W9 -> 40
B10: =R10 -> Sukehito shinnō | D10: =W10 -> 38 | E10: =X10 -> 23 | F10: =V10 -> 61 | G10: =MOD(D10, 10) -> 8 | H10: =MOD(E10, 10) -> 3 | I10: =MOD(F10, 10) -> 1 | J10: =MOD(INT(D10/10),10) -> 3 | K10: =MOD(INT(E10/10),10) -> 2 | L10: =MOD(INT(F10/10),10) -> 6 | M10: =MOD(INT(D10/100),10) -> 0 | N10: =MOD(INT(E10/100),10) -> 0 | O10: =MOD(INT(F10/100),10) -> 0 | Q10: 7 | R10: Sukehito shinnō | S10: 1733 | T10: 1794 | U10: =S9 -> 1771 | V10: =T10-S10 -> 61 | W10: =U10-S10 -> 38 | X10: =V10-W10 -> 23
B11: =R11 -> Naohito shinnō | D11: =W11 -> 29 | E11: =X11 -> 20 | F11: =V11 -> 49 | G11: =MOD(D11, 10) -> 9 | H11: =MOD(E11, 10) -> 0 | I11: =MOD(F11, 10) -> 9 | J11: =MOD(INT(D11/10),10) -> 2 | K11: =MOD(INT(E11/10),10) -> 2 | L11: =MOD(INT(F11/10),10) -> 4 | M11: =MOD(INT(D11/100),10) -> 0 | N11: =MOD(INT(E11/100),10) -> 0 | O11: =MOD(INT(F11/100),10) -> 0 | Q11: 8 | R11: Naohito shinnō | S11: 1704 | T11: 1753 | U11: =S10 -> 1733 | V11: =T11-S11 -> 49 | W11: =U11-S11 -> 29 | X11: =V11-W11 -> 20
B12: =R12 -> Asahito | D12: =W12 -> 29 | E12: =X12 -> 6 | F12: =V12 -> 35 | G12: =MOD(D12, 10) -> 9 | H12: =MOD(E12, 10) -> 6 | I12: =MOD(F12, 10) -> 5 | J12: =MOD(INT(D12/10),10) -> 2 | K12: =MOD(INT(E12/10),10) -> 0 | L12: =MOD(INT(F12/10),10) -> 3 | M12: =MOD(INT(D12/100),10) -> 0 | N12: =MOD(INT(E12/100),10) -> 0 | O12: =MOD(INT(F12/100),10) -> 0 | Q12: 9 | R12: Asahito | S12: 1675 | T12: 1710 | U12: =S11 -> 1704 | V12: =T12-S12 -> 35 | W12: =U12-S12 -> 29 | X12: =V12-W12 -> 6
B13: =R13 -> Satohito | D13: =W13 -> 21 | E13: =X13 -> 57 | F13: =V13 -> 78 | G13: =MOD(D13, 10) -> 1 | H13: =MOD(E13, 10) -> 7 | I13: =MOD(F13, 10) -> 8 | J13: =MOD(INT(D13/10),10) -> 2 | K13: =MOD(INT(E13/10),10) -> 5 | L13: =MOD(INT(F13/10),10) -> 7 | M13: =MOD(INT(D13/100),10) -> 0 | N13: =MOD(INT(E13/100),10) -> 0 | O13: =MOD(INT(F13/100),10) -> 0 | Q13: 10 | R13: Satohito | S13: 1654 | T13: 1732 | U13: =S12 -> 1675 | V13: =T13-S13 -> 78 | W13: =U13-S13 -> 21 | X13: =V13-W13 -> 57
B14: =R14 -> Kokohito | D14: =W14 -> 58 | E14: =X14 -> 26 | F14: =V14 -> 84 | G14: =MOD(D14, 10) -> 8 | H14: =MOD(E14, 10) -> 6 | I14: =MOD(F14, 10) -> 4 | J14: =MOD(INT(D14/10),10) -> 5 | K14: =MOD(INT(E14/10),10) -> 2 | L14: =MOD(INT(F14/10),10) -> 8 | M14: =MOD(INT(D14/100),10) -> 0 | N14: =MOD(INT(E14/100),10) -> 0 | O14: =MOD(INT(F14/100),10) -> 0 | Q14: 11 | R14: Kokohito | S14: 1596 | T14: 1680 | U14: =S13 -> 1654 | V14: =T14-S14 -> 84 | W14: =U14-S14 -> 58 | X14: =V14-W14 -> 26
B15: =R15 -> Kazuhito | D15: =W15 -> 24 | E15: =X15 -> 21 | F15: =V15 -> 45 | G15: =MOD(D15, 10) -> 4 | H15: =MOD(E15, 10) -> 1 | I15: =MOD(F15, 10) -> 5 | J15: =MOD(INT(D15/10),10) -> 2 | K15: =MOD(INT(E15/10),10) -> 2 | L15: =MOD(INT(F15/10),10) -> 4 | M15: =MOD(INT(D15/100),10) -> 0 | N15: =MOD(INT(E15/100),10) -> 0 | O15: =MOD(INT(F15/100),10) -> 0 | Q15: 12 | R15: Kazuhito | S15: 1572 | T15: 1617 | U15: =S14 -> 1596 | V15: =T15-S15 -> 45 | W15: =U15-S15 -> 24 | X15: =V15-W15 -> 21
B16: =R16 -> Prince Masahito | D16: =W16 -> 20 | E16: =X16 -> 14 | F16: =V16 -> 34 | G16: =MOD(D16, 10) -> 0 | H16: =MOD(E16, 10) -> 4 | I16: =MOD(F16, 10) -> 4 | J16: =MOD(INT(D16/10),10) -> 2 | K16: =MOD(INT(E16/10),10) -> 1 | L16: =MOD(INT(F16/10),10) -> 3 | M16: =MOD(INT(D16/100),10) -> 0 | N16: =MOD(INT(E16/100),10) -> 0 | O16: =MOD(INT(F16/100),10) -> 0 | Q16: 13 | R16: Prince Masahito | S16: 1552 | T16: 1586 | U16: =S15 -> 1572 | V16: =T16-S16 -> 34 | W16: =U16-S16 -> 20 | X16: =V16-W16 -> 14
... B22: =R22 -> Sadafusa shinnō | D22: =W22 -> 47 | E22: =X22 -> 37 | F22: =V22 -> 84 | G22: =MOD(D22, 10) -> 7 | H22: =MOD(E22, 10) -> 7 | I22: =MOD(F22, 10) -> 4 | J22: =MOD(INT(D22/10),10) -> 4 | K22: =MOD(INT(E22/10),10) -> 3 | L22: =MOD(INT(F22/10),10) -> 8 | M22: =MOD(INT(D22/100),10) -> 0 | N22: =MOD(INT(E22/100),10) -> 0 | O22: =MOD(INT(F22/100),10) -> 0 | Q22: 19 | R22: Sadafusa shinnō | S22: 1372 | T22: 1456 | U22: =S21 -> 1419 | V22: =T22-S22 -> 84 | W22: =U22-S22 -> 47 | X22: =V22-W22 -> 37
C23: total | D23: =SUM(D14:D22) -> 282 | E23: =SUM(E14:E22) -> 273 | F23: =SUM(F14:F22) -> 555
H26: calc | K26: calc | N26: calc
F27: 0 | G27: =COUNTIF(G$4:G$22,$F27) -> 2 | H27: =COUNTIF(H$4:H$22,$F27) -> 3 | I27: =COUNTIF(I$4:I$22,$F27) -> 2 | J27: =COUNTIF(J$4:J$22,$F27) -> 0 | K27: =COUNTIF(K$4:K$22,$F27) -> 1 | L27: =COUNTIF(L$4:L$22,$F27) -> 0 | M27: =COUNTIF(M$4:M$22,$F27) -> 19 | N27: =COUNTIF(N$4:N$22,$F27) -> 19 | O27: =COUNTIF(O$4:O$22,$F27) -> 19
F28: 1 | G28: =COUNTIF(G$4:G$22,$F28) -> 3 | H28: =COUNTIF(H$4:H$22,$F28) -> 2 | I28: =COUNTIF(I$4:I$22,$F28) -> 1 | J28: =COUNTIF(J$4:J$22,$F28) -> 0 | K28: =COUNTIF(K$4:K$22,$F28) -> 3 | L28: =COUNTIF(L$4:L$22,$F28) -> 0 | M28: =COUNTIF(M$4:M$22,$F28) -> 0 | N28: =COUNTIF(N$4:N$22,$F28) -> 0 | O28: =COUNTIF(O$4:O$22,$F28) -> 0
F29: 2 | G29: =COUNTIF(G$4:G$22,$F29) -> 3 | H29: =COUNTIF(H$4:H$22,$F29) -> 0 | I29: =COUNTIF(I$4:I$22,$F29) -> 2 | J29: =COUNTIF(J$4:J$22,$F29) -> 12 | K29: =COUNTIF(K$4:K$22,$F29) -> 7 | L29: =COUNTIF(L$4:L$22,$F29) -> 0 | M29: =COUNTIF(M$4:M$22,$F29) -> 0 | N29: =COUNTIF(N$4:N$22,$F29) -> 0 | O29: =COUNTIF(O$4:O$22,$F29) -> 0
F30: 3 | G30: =COUNTIF(G$4:G$22,$F30) -> 2 | H30: =COUNTIF(H$4:H$22,$F30) -> 2 | I30: =COUNTIF(I$4:I$22,$F30) -> 0 | J30: =COUNTIF(J$4:J$22,$F30) -> 5 | K30: =COUNTIF(K$4:K$22,$F30) -> 3 | L30: =COUNTIF(L$4:L$22,$F30) -> 3 | M30: =COUNTIF(M$4:M$22,$F30) -> 0 | N30: =COUNTIF(N$4:N$22,$F30) -> 0 | O30: =COUNTIF(O$4:O$22,$F30) -> 0
F31: 4 | G31: =COUNTIF(G$4:G$22,$F31) -> 1 | H31: =COUNTIF(H$4:H$22,$F31) -> 1 | I31: =COUNTIF(I$4:I$22,$F31) -> 3 | J31: =COUNTIF(J$4:J$22,$F31) -> 1 | K31: =COUNTIF(K$4:K$22,$F31) -> 3 | L31: =COUNTIF(L$4:L$22,$F31) -> 4 | M31: =COUNTIF(M$4:M$22,$F31) -> 0 | N31: =COUNTIF(N$4:N$22,$F31) -> 0 | O31: =COUNTIF(O$4:O$22,$F31) -> 0
F32: 5 | G32: =COUNTIF(G$4:G$22,$F32) -> 1 | H32: =COUNTIF(H$4:H$22,$F32) -> 3 | I32: =COUNTIF(I$4:I$22,$F32) -> 2 | J32: =COUNTIF(J$4:J$22,$F32) -> 1 | K32: =COUNTIF(K$4:K$22,$F32) -> 2 | L32: =COUNTIF(L$4:L$22,$F32) -> 2 | M32: =COUNTIF(M$4:M$22,$F32) -> 0 | N32: =COUNTIF(N$4:N$22,$F32) -> 0 | O32: =COUNTIF(O$4:O$22,$F32) -> 0
F33: 6 | G33: =COUNTIF(G$4:G$22,$F33) -> 0 | H33: =COUNTIF(H$4:H$22,$F33) -> 4 | I33: =COUNTIF(I$4:I$22,$F33) -> 3 | J33: =COUNTIF(J$4:J$22,$F33) -> 0 | K33: =COUNTIF(K$4:K$22,$F33) -> 0 | L33: =COUNTIF(L$4:L$22,$F33) -> 5 | M33: =COUNTIF(M$4:M$22,$F33) -> 0 | N33: =COUNTIF(N$4:N$22,$F33) -> 0 | O33: =COUNTIF(O$4:O$22,$F33) -> 0
F34: 7 | G34: =COUNTIF(G$4:G$22,$F34) -> 2 | H34: =COUNTIF(H$4:H$22,$F34) -> 2 | I34: =COUNTIF(I$4:I$22,$F34) -> 1 | J34: =COUNTIF(J$4:J$22,$F34) -> 0 | K34: =COUNTIF(K$4:K$22,$F34) -> 0 | L34: =COUNTIF(L$4:L$22,$F34) -> 2 | M34: =COUNTIF(M$4:M$22,$F34) -> 0 | N34: =COUNTIF(N$4:N$22,$F34) -> 0 | O34: =COUNTIF(O$4:O$22,$F34) -> 0
F35: 8 | G35: =COUNTIF(G$4:G$22,$F35) -> 2 | H35: =COUNTIF(H$4:H$22,$F35) -> 0 | I35: =COUNTIF(I$4:I$22,$F35) -> 3 | J35: =COUNTIF(J$4:J$22,$F35) -> 0 | K35: =COUNTIF(K$4:K$22,$F35) -> 0 | L35: =COUNTIF(L$4:L$22,$F35) -> 3 | M35: =COUNTIF(M$4:M$22,$F35) -> 0 | N35: =COUNTIF(N$4:N$22,$F35) -> 0 | O35: =COUNTIF(O$4:O$22,$F35) -> 0
F36: 9 | G36: =COUNTIF(G$4:G$22,$F36) -> 3 | H36: =COUNTIF(H$4:H$22,$F36) -> 2 | I36: =COUNTIF(I$4:I$22,$F36) -> 2 | J36: =COUNTIF(J$4:J$22,$F36) -> 0 | K36: =COUNTIF(K$4:K$22,$F36) -> 0 | L36: =COUNTIF(L$4:L$22,$F36) -> 0 | M36: =COUNTIF(M$4:M$22,$F36) -> 0 | N36: =COUNTIF(N$4:N$22,$F36) -> 0 | O36: =COUNTIF(O$4:O$22,$F36) -> 0

Sheet Fig_2A_decomp
B2: genealogy | D2: Actual ages | G2: digit of 1s column | J2: digit of 10s column | M2: digit of 100s column
B3: Father | C3: Son | D3: Age of father at sons birth | E3: years after sons birth | F3: total age of father | G3: Age of father at sons birth | H3: years after sons birth | I3: total age of father | J3: Age of father at sons birth | K3: years after sons birth | L3: total age of father | M3: Age of father at sons birth | N3: years after sons birth | O3: total age of father
B4: Adam | C4: Seth | D4: 130 | E4: 800 | F4: 930 | G4: =MOD(D4, 10) -> 0 | H4: =MOD(E4, 10) -> 0 | I4: =MOD(F4, 10) -> 0 | J4: =MOD(INT(D4/10),10) -> 3 | K4: =MOD(INT(E4/10),10) -> 0 | L4: =MOD(INT(F4/10),10) -> 3 | M4: =MOD(INT(D4/100),10) -> 1 | N4: =MOD(INT(E4/100),10) -> 8 | O4: =MOD(INT(F4/100),10) -> 9
B5: Seth | C5: Enosh | D5: 105 | E5: 807 | F5: 912 | G5: =MOD(D5, 10) -> 5 | H5: =MOD(E5, 10) -> 7 | I5: =MOD(F5, 10) -> 2 | J5: =MOD(INT(D5/10),10) -> 0 | K5: =MOD(INT(E5/10),10) -> 0 | L5: =MOD(INT(F5/10),10) -> 1 | M5: =MOD(INT(D5/100),10) -> 1 | N5: =MOD(INT(E5/100),10) -> 8 | O5: =MOD(INT(F5/100),10) -> 9
B6: Enosh | C6: Kenan | D6: 90 | E6: 815 | F6: 905 | G6: =MOD(D6, 10) -> 0 | H6: =MOD(E6, 10) -> 5 | I6: =MOD(F6, 10) -> 5 | J6: =MOD(INT(D6/10),10) -> 9 | K6: =MOD(INT(E6/10),10) -> 1 | L6: =MOD(INT(F6/10),10) -> 0 | M6: =MOD(INT(D6/100),10) -> 0 | N6: =MOD(INT(E6/100),10) -> 8 | O6: =MOD(INT(F6/100),10) -> 9
B7: Kenan | C7: Mahalalel | D7: 70 | E7: 840 | F7: 910 | G7: =MOD(D7, 10) -> 0 | H7: =MOD(E7, 10) -> 0 | I7: =MOD(F7, 10) -> 0 | J7: =MOD(INT(D7/10),10) -> 7 | K7: =MOD(INT(E7/10),10) -> 4 | L7: =MOD(INT(F7/10),10) -> 1 | M7: =MOD(INT(D7/100),10) -> 0 | N7: =MOD(INT(E7/100),10) -> 8 | O7: =MOD(INT(F7/100),10) -> 9
B8: Mahalalel | C8: Jared | D8: 65 | E8: 830 | F8: 895 | G8: =MOD(D8, 10) -> 5 | H8: =MOD(E8, 10) -> 0 | I8: =MOD(F8, 10) -> 5 | J8: =MOD(INT(D8/10),10) -> 6 | K8: =MOD(INT(E8/10),10) -> 3 | L8: =MOD(INT(F8/10),10) -> 9 | M8: =MOD(INT(D8/100),10) -> 0 | N8: =MOD(INT(E8/100),10) -> 8 | O8: =MOD(INT(F8/100),10) -> 8
B9: Jared | C9: Enoch | D9: 162 | E9: 800 | F9: 962 | G9: =MOD(D9, 10) -> 2 | H9: =MOD(E9, 10) -> 0 | I9: =MOD(F9, 10) -> 2 | J9: =MOD(INT(D9/10),10) -> 6 | K9: =MOD(INT(E9/10),10) -> 0 | L9: =MOD(INT(F9/10),10) -> 6 | M9: =MOD(INT(D9/100),10) -> 1 | N9: =MOD(INT(E9/100),10) -> 8 | O9: =MOD(INT(F9/100),10) -> 9
B10: Enoch | C10: Methuselah | D10: 65 | E10: 300 | F10: 365 | G10: =MOD(D10, 10) -> 5 | H10: =MOD(E10, 10) -> 0 | I10: =MOD(F10, 10) -> 5 | J10: =MOD(INT(D10/10),10) -> 6 | K10: =MOD(INT(E10/10),10) -> 0 | L10: =MOD(INT(F10/10),10) -> 6 | M10: =MOD(INT(D10/100),10) -> 0 | N10: =MOD(INT(E10/100),10) -> 3 | O10: =MOD(INT(F10/100),10) -> 3
B11: Methuselah | C11: Lamech | D11: 187 | E11: 782 | F11: 969 | G11: =MOD(D11, 10) -> 7 | H11: =MOD(E11, 10) -> 2 | I11: =MOD(F11, 10) -> 9 | J11: =MOD(INT(D11/10),10) -> 8 | K11: =MOD(INT(E11/10),10) -> 8 | L11: =MOD(INT(F11/10),10) -> 6 | M11: =MOD(INT(D11/100),10) -> 1 | N11: =MOD(INT(E11/100),10) -> 7 | O11: =MOD(INT(F11/100),10) -> 9
B12: Lamech | C12: Noah | D12: 182 | E12: 595 | F12: 777 | G12: =MOD(D12, 10) -> 2 | H12: =MOD(E12, 10) -> 5 | I12: =MOD(F12, 10) -> 7 | J12: =MOD(INT(D12/10),10) -> 8 | K12: =MOD(INT(E12/10),10) -> 9 | L12: =MOD(INT(F12/10),10) -> 7 | M12: =MOD(INT(D12/100),10) -> 1 | N12: =MOD(INT(E12/100),10) -> 5 | O12: =MOD(INT(F12/100),10) -> 7
B13: Noah | C13: Shem | D13: 500 | E13: 450 | F13: 950 | G13: =MOD(D13, 10) -> 0 | H13: =MOD(E13, 10) -> 0 | I13: =MOD(F13, 10) -> 0 | J13: =MOD(INT(D13/10),10) -> 0 | K13: =MOD(INT(E13/10),10) -> 5 | L13: =MOD(INT(F13/10),10) -> 5 | M13: =MOD(INT(D13/100),10) -> 5 | N13: =MOD(INT(E13/100),10) -> 4 | O13: =MOD(INT(F13/100),10) -> 9
C14: total | D14: =SUM(D4:D13) -> 1556 | E14: =SUM(E4:E13) -> 7019 | F14: =SUM(F4:F13) -> 8575
G15: excluding calculated values
B16: Adam | C16: Seth | D16: 130 | E16: 800 | F16: 930 | G16: =MOD(D16, 10) -> 0 | H16: =MOD(E16, 10) -> 0 | I16: =MOD(F16, 10) -> 0 | J16: =MOD(INT(D16/10),10) -> 3 | K16: =MOD(INT(E16/10),10) -> 0 | L16: =MOD(INT(F16/10),10) -> 3 | M16: =MOD(INT(D16/100),10) -> 1 | N16: =MOD(INT(E16/100),10) -> 8 | O16: =MOD(INT(F16/100),10) -> 9
B17: Seth | C17: Enosh | D17: 105 | E17: 807 | F17: 912 | G17: =MOD(D17, 10) -> 5 | H17: =MOD(E17, 10) -> 7 | I17: =MOD(F17, 10) -> 2 | J17: =MOD(INT(D17/10),10) -> 0 | K17: =MOD(INT(E17/10),10) -> 0 | L17: =MOD(INT(F17/10),10) -> 1 | M17: =MOD(INT(D17/100),10) -> 1 | N17: =MOD(INT(E17/100),10) -> 8 | O17: =MOD(INT(F17/100),10) -> 9
B18: Enosh | C18: Kenan | D18: 90 | E18: 815 | F18: 905 | G18: =MOD(D18, 10) -> 0 | H18: =MOD(E18, 10) -> 5 | I18: =MOD(F18, 10) -> 5 | J18: =MOD(INT(D18/10),10) -> 9 | K18: =MOD(INT(E18/10),10) -> 1 | L18: =MOD(INT(F18/10),10) -> 0 | M18: =MOD(INT(D18/100),10) -> 0 | N18: =MOD(INT(E18/100),10) -> 8 | O18: =MOD(INT(F18/100),10) -> 9
B19: Kenan | C19: Mahalalel | D19: 70 | E19: 840 | F19: 910 | G19: =MOD(D19, 10) -> 0 | H19: =MOD(E19, 10) -> 0 | I19: =MOD(F19, 10) -> 0 | J19: =MOD(INT(D19/10),10) -> 7 | K19: =MOD(INT(E19/10),10) -> 4 | L19: =MOD(INT(F19/10),10) -> 1 | M19: =MOD(INT(D19/100),10) -> 0 | N19: =MOD(INT(E19/100),10) -> 8 | O19: =MOD(INT(F19/100),10) -> 9
B20: Mahalalel | C20: Jared | D20: 65 | E20: 830 | F20: 895 | G20: =MOD(D20, 10) -> 5 | H20: =MOD(E20, 10) -> 0 | I20: =MOD(F20, 10) -> 5 | J20: =MOD(INT(D20/10),10) -> 6 | K20: =MOD(INT(E20/10),10) -> 3 | L20: =MOD(INT(F20/10),10) -> 9 | M20: =MOD(INT(D20/100),10) -> 0 | N20: =MOD(INT(E20/100),10) -> 8 | O20: =MOD(INT(F20/100),10) -> 8
B21: Jared | C21: Enoch | D21: 162 | E21: 800 | F21: 962 | G21: =MOD(D21, 10) -> 2 | H21: =MOD(E21, 10) -> 0 | I21: =MOD(F21, 10) -> 2 | J21: =MOD(INT(D21/10),10) -> 6 | K21: =MOD(INT(E21/10),10) -> 0 | L21: =MOD(INT(F21/10),10) -> 6 | M21: =MOD(INT(D21/100),10) -> 1 | N21: =MOD(INT(E21/100),10) -> 8 | O21: =MOD(INT(F21/100),10) -> 9
B22: Enoch | C22: Methuselah | D22: 65 | E22: 300 | F22: 365 | G22: =MOD(D22, 10) -> 5 | H22: =MOD(E22, 10) -> 0 | I22: =MOD(F22, 10) -> 5 | J22: =MOD(INT(D22/10),10) -> 6 | K22: =MOD(INT(E22/10),10) -> 0 | L22: =MOD(INT(F22/10),10) -> 6 | M22: =MOD(INT(D22/100),10) -> 0 | N22: =MOD(INT(E22/100),10) -> 3 | O22: =MOD(INT(F22/100),10) -> 3
B23: Methuselah | C23: Lamech | D23: 187 | E23: 782 | F23: 969 | G23: =MOD(D23, 10) -> 7 | H23: =MOD(E23, 10) -> 2 | I23: =MOD(F23, 10) -> 9 | J23: =MOD(INT(D23/10),10) -> 8 | K23: =MOD(INT(E23/10),10) -> 8 | L23: =MOD(INT(F23/10),10) -> 6 | M23: =MOD(INT(D23/100),10) -> 1 | N23: =MOD(INT(E23/100),10) -> 7 | O23: =MOD(INT(F23/100),10) -> 9
B24: Lamech | C24: Noah | D24: 182 | E24: 595 | F24: 777 | G24: =MOD(D24, 10) -> 2 | H24: =MOD(E24, 10) -> 5 | I24: =MOD(F24, 10) -> 7 | J24: =MOD(INT(D24/10),10) -> 8 | K24: =MOD(INT(E24/10),10) -> 9 | L24: =MOD(INT(F24/10),10) -> 7 | M24: =MOD(INT(D24/100),10) -> 1 | N24: =MOD(INT(E24/100),10) -> 5 | O24: =MOD(INT(F24/100),10) -> 7
B25: Noah | C25: Shem | D25: 500 | F25: 950 | G25: =MOD(D25, 10) -> 0 | I25: =MOD(F25, 10) -> 0 | J25: =MOD(INT(D25/10),10) -> 0 | L25: =MOD(INT(F25/10),10) -> 5 | M25: =MOD(INT(D25/100),10) -> 5 | O25: =MOD(INT(F25/100),10) -> 9
F29: 0 | G29: =COUNTIF(G$4:G$13,$F29) -> 4 | H29: =COUNTIF(H$4:H$13,$F29) -> 6 | I29: =COUNTIF(I$4:I$13,$F29) -> 3 | J29: =COUNTIF(J$4:J$13,$F29) -> 2 | K29: =COUNTIF(K$4:K$13,$F29) -> 4 | L29: =COUNTIF(L$4:L$13,$F29) -> 1 | M29: =COUNTIF(M$4:M$13,$F29) -> 4 | N29: =COUNTIF(N$4:N$13,$F29) -> 0 | O29: =COUNTIF(O$4:O$13,$F29) -> 0
F30: 1 | G30: =COUNTIF(G$4:G$13,$F30) -> 0 | H30: =COUNTIF(H$4:H$13,$F30) -> 0 | I30: =COUNTIF(I$4:I$13,$F30) -> 0 | J30: =COUNTIF(J$4:J$13,$F30) -> 0 | K30: =COUNTIF(K$4:K$13,$F30) -> 1 | L30: =COUNTIF(L$4:L$13,$F30) -> 2 | M30: =COUNTIF(M$4:M$13,$F30) -> 5 | N30: =COUNTIF(N$4:N$13,$F30) -> 0 | O30: =COUNTIF(O$4:O$13,$F30) -> 0
F31: 2 | G31: =COUNTIF(G$4:G$13,$F31) -> 2 | H31: =COUNTIF(H$4:H$13,$F31) -> 1 | I31: =COUNTIF(I$4:I$13,$F31) -> 2 | J31: =COUNTIF(J$4:J$13,$F31) -> 0 | K31: =COUNTIF(K$4:K$13,$F31) -> 0 | L31: =COUNTIF(L$4:L$13,$F31) -> 0 | M31: =COUNTIF(M$4:M$13,$F31) -> 0 | N31: =COUNTIF(N$4:N$13,$F31) -> 0 | O31: =COUNTIF(O$4:O$13,$F31) -> 0
F32: 3 | G32: =COUNTIF(G$4:G$13,$F32) -> 0 | H32: =COUNTIF(H$4:H$13,$F32) -> 0 | I32: =COUNTIF(I$4:I$13,$F32) -> 0 | J32: =COUNTIF(J$4:J$13,$F32) -> 1 | K32: =COUNTIF(K$4:K$13,$F32) -> 1 | L32: =COUNTIF(L$4:L$13,$F32) -> 1 | M32: =COUNTIF(M$4:M$13,$F32) -> 0 | N32: =COUNTIF(N$4:N$13,$F32) -> 1 | O32: =COUNTIF(O$4:O$13,$F32) -> 1
F33: 4 | G33: =COUNTIF(G$4:G$13,$F33) -> 0 | H33: =COUNTIF(H$4:H$13,$F33) -> 0 | I33: =COUNTIF(I$4:I$13,$F33) -> 0 | J33: =COUNTIF(J$4:J$13,$F33) -> 0 | K33: =COUNTIF(K$4:K$13,$F33) -> 1 | L33: =COUNTIF(L$4:L$13,$F33) -> 0 | M33: =COUNTIF(M$4:M$13,$F33) -> 0 | N33: =COUNTIF(N$4:N$13,$F33) -> 1 | O33: =COUNTIF(O$4:O$13,$F33) -> 0
F34: 5 | G34: =COUNTIF(G$4:G$13,$F34) -> 3 | H34: =COUNTIF(H$4:H$13,$F34) -> 2 | I34: =COUNTIF(I$4:I$13,$F34) -> 3 | J34: =COUNTIF(J$4:J$13,$F34) -> 0 | K34: =COUNTIF(K$4:K$13,$F34) -> 1 | L34: =COUNTIF(L$4:L$13,$F34) -> 1 | M34: =COUNTIF(M$4:M$13,$F34) -> 1 | N34: =COUNTIF(N$4:N$13,$F34) -> 1 | O34: =COUNTIF(O$4:O$13,$F34) -> 0
F35: 6 | G35: =COUNTIF(G$4:G$13,$F35) -> 0 | H35: =COUNTIF(H$4:H$13,$F35) -> 0 | I35: =COUNTIF(I$4:I$13,$F35) -> 0 | J35: =COUNTIF(J$4:J$13,$F35) -> 3 | K35: =COUNTIF(K$4:K$13,$F35) -> 0 | L35: =COUNTIF(L$4:L$13,$F35) -> 3 | M35: =COUNTIF(M$4:M$13,$F35) -> 0 | N35: =COUNTIF(N$4:N$13,$F35) -> 0 | O35: =COUNTIF(O$4:O$13,$F35) -> 0
F36: 7 | G36: =COUNTIF(G$4:G$13,$F36) -> 1 | H36: =COUNTIF(H$4:H$13,$F36) -> 1 | I36: =COUNTIF(I$4:I$13,$F36) -> 1 | J36: =COUNTIF(J$4:J$13,$F36) -> 1 | K36: =COUNTIF(K$4:K$13,$F36) -> 0 | L36: =COUNTIF(L$4:L$13,$F36) -> 1 | M36: =COUNTIF(M$4:M$13,$F36) -> 0 | N36: =COUNTIF(N$4:N$13,$F36) -> 1 | O36: =COUNTIF(O$4:O$13,$F36) -> 1
F37: 8 | G37: =COUNTIF(G$4:G$13,$F37) -> 0 | H37: =COUNTIF(H$4:H$13,$F37) -> 0 | I37: =COUNTIF(I$4:I$13,$F37) -> 0 | J37: =COUNTIF(J$4:J$13,$F37) -> 2 | K37: =COUNTIF(K$4:K$13,$F37) -> 1 | L37: =COUNTIF(L$4:L$13,$F37) -> 0 | M37: =COUNTIF(M$4:M$13,$F37) -> 0 | N37: =COUNTIF(N$4:N$13,$F37) -> 6 | O37: =COUNTIF(O$4:O$13,$F37) -> 1
F38: 9 | G38: =COUNTIF(G$4:G$13,$F38) -> 0 | H38: =COUNTIF(H$4:H$13,$F38) -> 0 | I38: =COUNTIF(I$4:I$13,$F38) -> 1 | J38: =COUNTIF(J$4:J$13,$F38) -> 1 | K38: =COUNTIF(K$4:K$13,$F38) -> 1 | L38: =COUNTIF(L$4:L$13,$F38) -> 1 | M38: =COUNTIF(M$4:M$13,$F38) -> 0 | N38: =COUNTIF(N$4:N$13,$F38) -> 0 | O38: =COUNTIF(O$4:O$13,$F38) -> 7

Sheet Fig_2B_decomp
B2: genealogy | D2: Actual ages | G2: digit of 1s column | J2: digit of 10s column | M2: digit of 100s column
B3: Father | C3: Son | D3: Age of father at sons birth | E3: years after sons birth | F3: total age of father | G3: Age of father at sons birth | H3: years after sons birth | I3: total age of father | J3: Age of father at sons birth | K3: years after sons birth | L3: total age of father | M3: Age of father at sons birth | N3: years after sons birth | O3: total age of father
B4: Shem | C4: Arpachshad | D4: 100 | E4: 500 | F4: =D4+E4 -> 600 | G4: =MOD(D4, 10) -> 0 | H4: =MOD(E4, 10) -> 0 | I4: =MOD(F4, 10) -> 0 | J4: =MOD(INT(D4/10),10) -> 0 | K4: =MOD(INT(E4/10),10) -> 0 | L4: =MOD(INT(F4/10),10) -> 0 | M4: =MOD(INT(D4/100),10) -> 1 | N4: =MOD(INT(E4/100),10) -> 5 | O4: =MOD(INT(F4/100),10) -> 6
B5: Arpachshad | C5: Shelah | D5: 35 | E5: 403 | F5: =D5+E5 -> 438 | G5: =MOD(D5, 10) -> 5 | H5: =MOD(E5, 10) -> 3 | I5: =MOD(F5, 10) -> 8 | J5: =MOD(INT(D5/10),10) -> 3 | K5: =MOD(INT(E5/10),10) -> 0 | L5: =MOD(INT(F5/10),10) -> 3 | M5: =MOD(INT(D5/100),10) -> 0 | N5: =MOD(INT(E5/100),10) -> 4 | O5: =MOD(INT(F5/100),10) -> 4
B6: Shelah | C6: Eber | D6: 30 | E6: 403 | F6: =D6+E6 -> 433 | G6: =MOD(D6, 10) -> 0 | H6: =MOD(E6, 10) -> 3 | I6: =MOD(F6, 10) -> 3 | J6: =MOD(INT(D6/10),10) -> 3 | K6: =MOD(INT(E6/10),10) -> 0 | L6: =MOD(INT(F6/10),10) -> 3 | M6: =MOD(INT(D6/100),10) -> 0 | N6: =MOD(INT(E6/100),10) -> 4 | O6: =MOD(INT(F6/100),10) -> 4
B7: Eber | C7: Peleg | D7: 34 | E7: 430 | F7: =D7+E7 -> 464 | G7: =MOD(D7, 10) -> 4 | H7: =MOD(E7, 10) -> 0 | I7: =MOD(F7, 10) -> 4 | J7: =MOD(INT(D7/10),10) -> 3 | K7: =MOD(INT(E7/10),10) -> 3 | L7: =MOD(INT(F7/10),10) -> 6 | M7: =MOD(INT(D7/100),10) -> 0 | N7: =MOD(INT(E7/100),10) -> 4 | O7: =MOD(INT(F7/100),10) -> 4
B8: Peleg | C8: Reu | D8: 30 | E8: 209 | F8: =D8+E8 -> 239 | G8: =MOD(D8, 10) -> 0 | H8: =MOD(E8, 10) -> 9 | I8: =MOD(F8, 10) -> 9 | J8: =MOD(INT(D8/10),10) -> 3 | K8: =MOD(INT(E8/10),10) -> 0 | L8: =MOD(INT(F8/10),10) -> 3 | M8: =MOD(INT(D8/100),10) -> 0 | N8: =MOD(INT(E8/100),10) -> 2 | O8: =MOD(INT(F8/100),10) -> 2
B9: Reu | C9: Serug | D9: 32 | E9: 207 | F9: =D9+E9 -> 239 | G9: =MOD(D9, 10) -> 2 | H9: =MOD(E9, 10) -> 7 | I9: =MOD(F9, 10) -> 9 | J9: =MOD(INT(D9/10),10) -> 3 | K9: =MOD(INT(E9/10),10) -> 0 | L9: =MOD(INT(F9/10),10) -> 3 | M9: =MOD(INT(D9/100),10) -> 0 | N9: =MOD(INT(E9/100),10) -> 2 | O9: =MOD(INT(F9/100),10) -> 2
B10: Serug | C10: Nahor | D10: 30 | E10: 200 | F10: =D10+E10 -> 230 | G10: =MOD(D10, 10) -> 0 | H10: =MOD(E10, 10) -> 0 | I10: =MOD(F10, 10) -> 0 | J10: =MOD(INT(D10/10),10) -> 3 | K10: =MOD(INT(E10/10),10) -> 0 | L10: =MOD(INT(F10/10),10) -> 3 | M10: =MOD(INT(D10/100),10) -> 0 | N10: =MOD(INT(E10/100),10) -> 2 | O10: =MOD(INT(F10/100),10) -> 2
B11: Nahor | C11: Terah | D11: 29 | E11: 119 | F11: =D11+E11 -> 148 | G11: =MOD(D11, 10) -> 9 | H11: =MOD(E11, 10) -> 9 | I11: =MOD(F11, 10) -> 8 | J11: =MOD(INT(D11/10),10) -> 2 | K11: =MOD(INT(E11/10),10) -> 1 | L11: =MOD(INT(F11/10),10) -> 4 | M11: =MOD(INT(D11/100),10) -> 0 | N11: =MOD(INT(E11/100),10) -> 1 | O11: =MOD(INT(F11/100),10) -> 1
B12: Terah | C12: Abram | D12: 70 | E12: =F12-D12 -> 135 | F12: 205 | G12: =MOD(D12, 10) -> 0 | H12: =MOD(E12, 10) -> 5 | I12: =MOD(F12, 10) -> 5 | J12: =MOD(INT(D12/10),10) -> 7 | K12: =MOD(INT(E12/10),10) -> 3 | L12: =MOD(INT(F12/10),10) -> 0 | M12: =MOD(INT(D12/100),10) -> 0 | N12: =MOD(INT(E12/100),10) -> 1 | O12: =MOD(INT(F12/100),10) -> 2
C13: total | D13: =SUM(D4:D12) -> 390 | E13: =SUM(E4:E12) -> 2606 | F13: =SUM(F4:F12) -> 2996
G14: excluding calculated values
B15: Shem | C15: Arpachshad | D15: 100 | E15: 500 | G15: =MOD(D15, 10) -> 0 | H15: =MOD(E15, 10) -> 0 | J15: =MOD(INT(D15/10),10) -> 0 | K15: =MOD(INT(E15/10),10) -> 0 | M15: =MOD(INT(D15/100),10) -> 1 | N15: =MOD(INT(E15/100),10) -> 5
B16: Arpachshad | C16: Shelah | D16: 35 | E16: 403 | G16: =MOD(D16, 10) -> 5 | H16: =MOD(E16, 10) -> 3 | J16: =MOD(INT(D16/10),10) -> 3 | K16: =MOD(INT(E16/10),10) -> 0 | M16: =MOD(INT(D16/100),10) -> 0 | N16: =MOD(INT(E16/100),10) -> 4
B17: Shelah | C17: Eber | D17: 30 | E17: 403 | G17: =MOD(D17, 10) -> 0 | H17: =MOD(E17, 10) -> 3 | J17: =MOD(INT(D17/10),10) -> 3 | K17: =MOD(INT(E17/10),10) -> 0 | M17: =MOD(INT(D17/100),10) -> 0 | N17: =MOD(INT(E17/100),10) -> 4
B18: Eber | C18: Peleg | D18: 34 | E18: 430 | G18: =MOD(D18, 10) -> 4 | H18: =MOD(E18, 10) -> 0 | J18: =MOD(INT(D18/10),10) -> 3 | K18: =MOD(INT(E18/10),10) -> 3 | M18: =MOD(INT(D18/100),10) -> 0 | N18: =MOD(INT(E18/100),10) -> 4
B19: Peleg | C19: Reu | D19: 30 | E19: 209 | G19: =MOD(D19, 10) -> 0 | H19: =MOD(E19, 10) -> 9 | J19: =MOD(INT(D19/10),10) -> 3 | K19: =MOD(INT(E19/10),10) -> 0 | M19: =MOD(INT(D19/100),10) -> 0 | N19: =MOD(INT(E19/100),10) -> 2
B20: Reu | C20: Serug | D20: 32 | E20: 207 | G20: =MOD(D20, 10) -> 2 | H20: =MOD(E20, 10) -> 7 | J20: =MOD(INT(D20/10),10) -> 3 | K20: =MOD(INT(E20/10),10) -> 0 | M20: =MOD(INT(D20/100),10) -> 0 | N20: =MOD(INT(E20/100),10) -> 2
B21: Serug | C21: Nahor | D21: 30 | E21: 200 | G21: =MOD(D21, 10) -> 0 | H21: =MOD(E21, 10) -> 0 | J21: =MOD(INT(D21/10),10) -> 3 | K21: =MOD(INT(E21/10),10) -> 0 | M21: =MOD(INT(D21/100),10) -> 0 | N21: =MOD(INT(E21/100),10) -> 2
B22: Nahor | C22: Terah | D22: 29 | E22: 119 | G22: =MOD(D22, 10) -> 9 | H22: =MOD(E22, 10) -> 9 | J22: =MOD(INT(D22/10),10) -> 2 | K22: =MOD(INT(E22/10),10) -> 1 | M22: =MOD(INT(D22/100),10) -> 0 | N22: =MOD(INT(E22/100),10) -> 1
B23: Terah | C23: Abram | D23: 70 | F23: 205 | G23: =MOD(D23, 10) -> 0 | I23: =MOD(F23, 10) -> 5 | J23: =MOD(INT(D23/10),10) -> 7 | L23: =MOD(INT(F23/10),10) -> 0 | M23: =MOD(INT(D23/100),10) -> 0 | O23: =MOD(INT(F23/100),10) -> 2
F27: 0 | G27: =COUNTIF(G$4:G$12,$F27) -> 5 | H27: =COUNTIF(H$4:H$12,$F27) -> 3 | I27: =COUNTIF(I$4:I$12,$F27) -> 2 | J27: =COUNTIF(J$4:J$12,$F27) -> 1 | K27: =COUNTIF(K$4:K$12,$F27) -> 6 | L27: =COUNTIF(L$4:L$12,$F27) -> 2 | M27: =COUNTIF(M$4:M$12,$F27) -> 8 | N27: =COUNTIF(N$4:N$12,$F27) -> 0 | O27: =COUNTIF(O$4:O$12,$F27) -> 0
F28: 1 | G28: =COUNTIF(G$4:G$12,$F28) -> 0 | H28: =COUNTIF(H$4:H$12,$F28) -> 0 | I28: =COUNTIF(I$4:I$12,$F28) -> 0 | J28: =COUNTIF(J$4:J$12,$F28) -> 0 | K28: =COUNTIF(K$4:K$12,$F28) -> 1 | L28: =COUNTIF(L$4:L$12,$F28) -> 0 | M28: =COUNTIF(M$4:M$12,$F28) -> 1 | N28: =COUNTIF(N$4:N$12,$F28) -> 2 | O28: =COUNTIF(O$4:O$12,$F28) -> 1
F29: 2 | G29: =COUNTIF(G$4:G$12,$F29) -> 1 | H29: =COUNTIF(H$4:H$12,$F29) -> 0 | I29: =COUNTIF(I$4:I$12,$F29) -> 0 | J29: =COUNTIF(J$4:J$12,$F29) -> 1 | K29: =COUNTIF(K$4:K$12,$F29) -> 0 | L29: =COUNTIF(L$4:L$12,$F29) -> 0 | M29: =COUNTIF(M$4:M$12,$F29) -> 0 | N29: =COUNTIF(N$4:N$12,$F29) -> 3 | O29: =COUNTIF(O$4:O$12,$F29) -> 4
F30: 3 | G30: =COUNTIF(G$4:G$12,$F30) -> 0 | H30: =COUNTIF(H$4:H$12,$F30) -> 2 | I30: =COUNTIF(I$4:I$12,$F30) -> 1 | J30: =COUNTIF(J$4:J$12,$F30) -> 6 | K30: =COUNTIF(K$4:K$12,$F30) -> 2 | L30: =COUNTIF(L$4:L$12,$F30) -> 5 | M30: =COUNTIF(M$4:M$12,$F30) -> 0 | N30: =COUNTIF(N$4:N$12,$F30) -> 0 | O30: =COUNTIF(O$4:O$12,$F30) -> 0
F31: 4 | G31: =COUNTIF(G$4:G$12,$F31) -> 1 | H31: =COUNTIF(H$4:H$12,$F31) -> 0 | I31: =COUNTIF(I$4:I$12,$F31) -> 1 | J31: =COUNTIF(J$4:J$12,$F31) -> 0 | K31: =COUNTIF(K$4:K$12,$F31) -> 0 | L31: =COUNTIF(L$4:L$12,$F31) -> 1 | M31: =COUNTIF(M$4:M$12,$F31) -> 0 | N31: =COUNTIF(N$4:N$12,$F31) -> 3 | O31: =COUNTIF(O$4:O$12,$F31) -> 3
F32: 5 | G32: =COUNTIF(G$4:G$12,$F32) -> 1 | H32: =COUNTIF(H$4:H$12,$F32) -> 1 | I32: =COUNTIF(I$4:I$12,$F32) -> 1 | J32: =COUNTIF(J$4:J$12,$F32) -> 0 | K32: =COUNTIF(K$4:K$12,$F32) -> 0 | L32: =COUNTIF(L$4:L$12,$F32) -> 0 | M32: =COUNTIF(M$4:M$12,$F32) -> 0 | N32: =COUNTIF(N$4:N$12,$F32) -> 1 | O32: =COUNTIF(O$4:O$12,$F32) -> 0
F33: 6 | G33: =COUNTIF(G$4:G$12,$F33) -> 0 | H33: =COUNTIF(H$4:H$12,$F33) -> 0 | I33: =COUNTIF(I$4:I$12,$F33) -> 0 | J33: =COUNTIF(J$4:J$12,$F33) -> 0 | K33: =COUNTIF(K$4:K$12,$F33) -> 0 | L33: =COUNTIF(L$4:L$12,$F33) -> 1 | M33: =COUNTIF(M$4:M$12,$F33) -> 0 | N33: =COUNTIF(N$4:N$12,$F33) -> 0 | O33: =COUNTIF(O$4:O$12,$F33) -> 1
F34: 7 | G34: =COUNTIF(G$4:G$12,$F34) -> 0 | H34: =COUNTIF(H$4:H$12,$F34) -> 1 | I34: =COUNTIF(I$4:I$12,$F34) -> 0 | J34: =COUNTIF(J$4:J$12,$F34) -> 1 | K34: =COUNTIF(K$4:K$12,$F34) -> 0 | L34: =COUNTIF(L$4:L$12,$F34) -> 0 | M34: =COUNTIF(M$4:M$12,$F34) -> 0 | N34: =COUNTIF(N$4:N$12,$F34) -> 0 | O34: =COUNTIF(O$4:O$12,$F34) -> 0
F35: 8 | G35: =COUNTIF(G$4:G$12,$F35) -> 0 | H35: =COUNTIF(H$4:H$12,$F35) -> 0 | I35: =COUNTIF(I$4:I$12,$F35) -> 2 | J35: =COUNTIF(J$4:J$12,$F35) -> 0 | K35: =COUNTIF(K$4:K$12,$F35) -> 0 | L35: =COUNTIF(L$4:L$12,$F35) -> 0 | M35: =COUNTIF(M$4:M$12,$F35) -> 0 | N35: =COUNTIF(N$4:N$12,$F35) -> 0 | O35: =COUNTIF(O$4:O$12,$F35) -> 0
F36: 9 | G36: =COUNTIF(G$4:G$12,$F36) -> 1 | H36: =COUNTIF(H$4:H$12,$F36) -> 2 | I36: =COUNTIF(I$4:I$12,$F36) -> 2 | J36: =COUNTIF(J$4:J$12,$F36) -> 0 | K36: =COUNTIF(K$4:K$12,$F36) -> 0 | L36: =COUNTIF(L$4:L$12,$F36) -> 0 | M36: =COUNTIF(M$4:M$12,$F36) -> 0 | N36: =COUNTIF(N$4:N$12,$F36) -> 0 | O36: =COUNTIF(O$4:O$12,$F36) -> 0

Sheet Fig_2C_decomp
B2: genealogy | D2: Actual ages | G2: digit of 1s column | J2: digit of 10s column | M2: digit of 100s column
B3: Father | C3: Son | D3: Age of father at sons birth | E3: years after sons birth | F3: total age of father | G3: Age of father at sons birth | H3: years after sons birth | I3: total age of father | J3: Age of father at sons birth | K3: years after sons birth | L3: total age of father | M3: Age of father at sons birth | N3: years after sons birth | O3: total age of father
B4: Adam | C4: Seth | D4: 130 | E4: 800 | F4: 930 | G4: =MOD(D4, 10) -> 0 | H4: =MOD(E4, 10) -> 0 | I4: =MOD(F4, 10) -> 0 | J4: =MOD(INT(D4/10),10) -> 3 | K4: =MOD(INT(E4/10),10) -> 0 | L4: =MOD(INT(F4/10),10) -> 3 | M4: =MOD(INT(D4/100),10) -> 1 | N4: =MOD(INT(E4/100),10) -> 8 | O4: =MOD(INT(F4/100),10) -> 9
B5: Seth | C5: Enosh | D5: 105 | E5: 807 | F5: 912 | G5: =MOD(D5, 10) -> 5 | H5: =MOD(E5, 10) -> 7 | I5: =MOD(F5, 10) -> 2 | J5: =MOD(INT(D5/10),10) -> 0 | K5: =MOD(INT(E5/10),10) -> 0 | L5: =MOD(INT(F5/10),10) -> 1 | M5: =MOD(INT(D5/100),10) -> 1 | N5: =MOD(INT(E5/100),10) -> 8 | O5: =MOD(INT(F5/100),10) -> 9
